Workbook

Sheet 00_说明
A1: 星序：元素防线 — 调参总表 v0.2（蒙特卡洛校准版）
A3: 本表所有经济公式已按 v0.2 的归一化方案重建。v0.1 的 xlsx 不可直接用于开发 —— 它的 CV 未归一化，跨档位膨胀 17 倍。
A5: 使用方式
A6: 黄色单元格 | B6: 可调输入参数。改动后全表公式自动重算。
A7: 绿色单元格 | B7: 公式计算结果。请勿手动覆盖，否则断链。
A8: 蓝色单元格 | B8: 蒙特卡洛实测值（300–400 局 x 5 档 x 3–4 种玩家策略）。有模拟脚本可复现，改动前请先看脚本注释。
A9: 灰色小字 | B9: 设计理由 / 调参方向说明。
A10: 无底色 | B10: 静态参考数据（文案表、卡池清单等）。
A12: 工作表导航
A13: 01_核心常量 | B13: 全局旋钮。所有其他表的输入源头，优先在这里调。
A14: 02_合成与充能 | B14: ★ 已归一化。方块值 -> 充能' / CV' / 各货币 / 附魔伤害，带档位选择器。
A15: 03_波次节奏模型 | B15: ★ 已归一化。每波步数、合成次数、CV'/波、小附魔/波 —— 跨档位应基本恒定。
A16: 04_关卡与敌人 | B16: ★ 换用新的技术模型（大数字达成率驱动）。1–15 关缩放与真实死亡关卡判定。
A17: 05_植物 | B17: ★ DPS 已下调至辅助定位。含元素效果表（火的 AoE 已封顶）。
A18: 06_卡牌 | B18: ★ 新增「战力点」列 —— 所有卡牌折算到同一把尺子，含超模/废卡处置建议。
A19: 07_风险决策EV | B19: 继续 / 收工的期望值计算器与保底比例敏感性分析。
A20: 08_养成与花园 | B20: 星尘养成树成本模型与花园产出模型。
A21: 09_验收清单 | B21: 平衡目标与「broken」判定标准 —— playtest 前先读这张。
A22: 10_波次预算表 | B22: ★ 新增。关 1 五波的完整输出 / HP 配平，是敌人基准数值的来源。
A24: v0.2 五项结构性修正（详见 GDD_星序防线_v0.2.md）
A25: M1 归一化 | B25: CV' = v / E[生成值]；充能' = k x log2(v/E) x 0.78(Jensen 修正)。原 CV 跨档膨胀 17 倍，归一化后波动 <2%。
A26: M2 弱分层 + 跨关保留 | B26: 分层增益 2.2x/档 -> 1.4x/档（强分层会让关 5 后技术倍差压到 1.0x）。棋盘跨关不重置。
A27: M3 输出占比翻转 | B27: 附魔 60% : 植物 40%（v0.1 实算是 21% : 79%，违反支柱 P2「合成即战斗」）。
A28: M4 AoE 封顶 / 删连锁 | B28: 元素总伤害池封顶 EP x 2.5 均分；连锁倍率会奖励乱滑，已删除。
A29: M5 术语去重 | B29: 核心(HP) -> 星枢；核心(货币) -> 晶核。
A31: 模拟脚本（纯 stdlib，python sim_xxx.py <每档局数>）：sim_board_v02.py / sim_board_v02b.py / sim_chain_v02c.py / sim_tier_v02d.py
A32: 配套文档：GDD_星序防线_v0.2.md（增量文档，未提及部分沿用 v0.1）

Sheet 01_核心常量
A1: 核心常量 —— 全局旋钮（黄底可调 / 蓝底为蒙特卡洛实测值，改这里会驱动全表）
A3: 分组 | B3: 参数名 | C3: 代号 | D3: 当前值 | E3: 建议范围 | F3: 调参说明
A4: 棋盘 | B4: 棋盘尺寸 | C4: BOARD_N | D4: 5 | E4: 5（不可改） | F4: ★ 实测：4x4 在生成值分层后关 3+ 卡死率 88–92%，5x5 卡死率 <1.5%。4x4 会直接毁掉游戏。
A5: 棋盘 | B5: 每次移动生成方块数 | C5: SPAWN_N | D5: 1 | E5: 1 – 2 | F5: 保持 1。卡牌「丰饶」可临时 +1（但该卡已判定破坏性超模，见 06 表）。
A6: 棋盘 | B6: 初始方块数 | C6: INIT_N | D6: 2 | E6: 2 – 4 | F6: 留出前期铺垫空间。
A7: 棋盘 | B7: 步数上限 | C7: STEP_MAX | D7: 5 | E7: 3 – 10 | F7: 攒满 5 步可打一套爆发连招，是「攒劲儿」的爽点来源。
A8: 棋盘 | B8: 步数回复间隔(秒) | C8: STEP_REGEN | D8: 1.5 | E8: 1.0 – 2.5 | F8: ★ 手感主旋钮。直接决定每波步数预算。
A9: 棋盘 | B9: 波次开局赠送步数 | C9: STEP_GIFT | D9: 2 | E9: 0 – 4 | F9: 缓解波次切换空窗。
A10: 棋盘 | B10: 每步平均合成次数 | C10: MERGE_RATE | D10: 0.9 | E10: 0.85 – 0.95 | F10: ★★ 实测 0.89–0.94，跨策略差异 <6%。v0.1 假设的 1.2 是错的。这是 2048 的结构性常数，不要把技术水平建在这个量上。
A11: 棋盘 | B11: 平均合成值 / E[生成] | C11: AVG_MERGE_COEF | D11: 5.47 | E11: 5.0 – 6.0 | F11: ★★ 实测：平均合成值 ≈ 5.47 x E[生成值]，跨全部 5 档稳定。所以归一化 CV'/波 = 合成次数 x 5.47，恒定。
A12: 棋盘 | B12: 充能 Jensen 修正 | C12: LOG_CORR | D12: 0.78 | E12: 0.70 – 0.85 | F12: ★★ 实测修正项。E[log2(v/E)] < log2(E[v]/E)，因为 log 是凹函数、合成值分布右偏。直接用 log2(均值) 会高估充能约 28%。
A13: 分层 | B13: 第1档生成期望 E | C13: E1 | D13: 2.2 | E13: — | F13: 关 1–2，生成池 2(90%)/4(10%)。该档技巧门槛：冲 256。
A14: 分层 | B14: 第2档生成期望 E | C14: E2 | D14: 3 | E14: — | F14: 关 3–4，生成池 2(70%)/4(20%)/8(10%)。
A15: 分层 | B15: 第3档生成期望 E | C15: E3 | D15: 4.8 | E15: — | F15: 关 5–6，生成池 4(80%)/8(20%)。该档技巧门槛：冲 512。
... A61: 养成 | B61: 养成树最大等级 | C61: TREE_MAX | D61: 10 | E61: 8 – 15 | F61: 每分支等级上限。

Sheet 02_合成与充能
A1: 方块值 → 充能' / CV' / 各货币 / 附魔伤害（★ v0.2 已归一化：CV' = v / E）
A3: 第一步：选择档位（改 B5 的 E 值切换，全表联动）
A4: 参数 | B4: 值 | C4: 说明
A5: 当前档位生成期望 E | B5: 2.2 | C5: 弱分层五档：2.2 / 3.0 / 4.8 / 6.0 / 9.6。改这个单元格即可切换档位查看换算。
A7: 弱分层五档参考（v0.2 M2）
A8: 档位 | B8: 关卡 | C8: 生成池 | D8: E[生成] | E8: 平均合成值 | F8: 该档技巧门槛 | G8: 合 256 的 CV' | H8: 合 512 的 CV'
A9: 1 | B9: 关 1–2 | C9: 2(90%)/4(10%) | D9: ='01_核心常量'!$D$13 | E9: =D9*'01_核心常量'!$D$11 | F9: 冲 256（熟练 37%） | G9: =256/D9 | H9: =512/D9
A10: 2 | B10: 关 3–4 | C10: 2(70%)/4(20%)/8(10%) | D10: ='01_核心常量'!$D$14 | E10: =D10*'01_核心常量'!$D$11 | F10: 冲 256 稳定化 | G10: =256/D10 | H10: =512/D10
A11: 3 | B11: 关 5–6 | C11: 4(80%)/8(20%) | D11: ='01_核心常量'!$D$15 | E11: =D11*'01_核心常量'!$D$11 | F11: 冲 512（熟练 58%） | G11: =256/D11 | H11: =512/D11
A12: 4 | B12: 关 7–9 | C12: 4(70%)/8(20%)/16(10%) | D12: ='01_核心常量'!$D$16 | E12: =D12*'01_核心常量'!$D$11 | F12: 冲 512 稳定化 | G12: =256/D12 | H12: =512/D12
A13: 5 | B13: 关 10+ | C13: 8(80%)/16(20%) | D13: ='01_核心常量'!$D$17 | E13: =D13*'01_核心常量'!$D$11 | F13: 冲 1024（熟练 57%） | G13: =256/D13 | H13: =512/D13
A15: ★ 归一化 CV' 的含义：它衡量「这次合成的难度」，不是数值大小。关 1 合出 256（占全局 78% 总价值）值 116 CV；关 10 合出 256 只是日常，只值 27 CV。同一份努力拿到同一份回报。
A16: ★ 注意「合 256 的 CV'」随档位下降 —— 这是刻意的：高关卡的 256 不再稀缺，救济感由更高的星级（512/1024）接棒。
A18: 换算总表（按上方 E 值计算）
A19: 方块值 v | B19: log₂v | C19: 充能' | D19: 是否超载 | E19: 品质 | F19: 威力系数 | G19: 附魔总伤害池 | H19: CV'(合成) | I19: CV'(升华) | J19: 星核 | K19: 晶核 | L19: 金币(关1) | M19: 碎片(关1)
A20: 4 | B20: 2 | C20: ='01_核心常量'!$D$20*LOG(A20/$B$5,2)*'01_核心常量'!$D$12 | D20: — | E20: — | F20: 1 | G20: ='01_核心常量'!$D$21*F20*'01_核心常量'!$D$22 | H20: =A20/$B$5 | I20: =IF(A20>='01_核心常量'!$D$29,A20/$B$5*'01_核心常量'!$D$28,0) | J20: =H20*'01_核心常量'!$D$25 | K20: 0 | L20: =H20*'01_核心常量'!$D$26 | M20: =H20*'01_核心常量'!$D$27
A21: 8 | B21: 3 | C21: ='01_核心常量'!$D$20*LOG(A21/$B$5,2)*'01_核心常量'!$D$12 | D21: — | E21: — | F21: 1 | G21: ='01_核心常量'!$D$21*F21*'01_核心常量'!$D$22 | H21: =A21/$B$5 | I21: =IF(A21>='01_核心常量'!$D$29,A21/$B$5*'01_核心常量'!$D$28,0) | J21: =H21*'01_核心常量'!$D$25 | K21: 0 | L21: =H21*'01_核心常量'!$D$26 | M21: =H21*'01_核心常量'!$D$27
A22: 16 | B22: 4 | C22: ='01_核心常量'!$D$20*LOG(A22/$B$5,2)*'01_核心常量'!$D$12 | D22: — | E22: — | F22: 1 | G22: ='01_核心常量'!$D$21*F22*'01_核心常量'!$D$22 | H22: =A22/$B$5 | I22: =IF(A22>='01_核心常量'!$D$29,A22/$B$5*'01_核心常量'!$D$28,0) | J22: =H22*'01_核心常量'!$D$25 | K22: 0 | L22: =H22*'01_核心常量'!$D$26 | M22: =H22*'01_核心常量'!$D$27
A23: 32 | B23: 5 | C23: ='01_核心常量'!$D$20*LOG(A23/$B$5,2)*'01_核心常量'!$D$12 | D23: — | E23: — | F23: 1 | G23: ='01_核心常量'!$D$21*F23*'01_核心常量'!$D$22 | H23: =A23/$B$5 | I23: =IF(A23>='01_核心常量'!$D$29,A23/$B$5*'01_核心常量'!$D$28,0) | J23: =H23*'01_核心常量'!$D$25 | K23: 0 | L23: =H23*'01_核心常量'!$D$26 | M23: =H23*'01_核心常量'!$D$27
A24: 64 | B24: 6 | C24: ='01_核心常量'!$D$20*LOG(A24/$B$5,2)*'01_核心常量'!$D$12 | D24: — | E24: — | F24: 1 | G24: ='01_核心常量'!$D$21*F24*'01_核心常量'!$D$22 | H24: =A24/$B$5 | I24: =IF(A24>='01_核心常量'!$D$29,A24/$B$5*'01_核心常量'!$D$28,0) | J24: =H24*'01_核心常量'!$D$25 | K24: 0 | L24: =H24*'01_核心常量'!$D$26 | M24: =H24*'01_核心常量'!$D$27
A25: 128 | B25: 7 | C25: ='01_核心常量'!$D$20*LOG(A25/$B$5,2)*'01_核心常量'!$D$12 | D25: — | E25: — | F25: 1 | G25: ='01_核心常量'!$D$21*F25*'01_核心常量'!$D$22 | H25: =A25/$B$5 | I25: =IF(A25>='01_核心常量'!$D$29,A25/$B$5*'01_核心常量'!$D$28,0) | J25: =H25*'01_核心常量'!$D$25 | K25: 1 | L25: =H25*'01_核心常量'!$D$26 | M25: =H25*'01_核心常量'!$D$27
A26: 256 | B26: 8 | C26: ='01_核心常量'!$D$20*LOG(A26/$B$5,2)*'01_核心常量'!$D$12 | D26: 超载 | E26: 1★ | F26: 2 | G26: ='01_核心常量'!$D$21*F26*'01_核心常量'!$D$22 | H26: =A26/$B$5 | I26: =IF(A26>='01_核心常量'!$D$29,A26/$B$5*'01_核心常量'!$D$28,0) | J26: =H26*'01_核心常量'!$D$25 | K26: 1 | L26: =H26*'01_核心常量'!$D$26 | M26: =H26*'01_核心常量'!$D$27
A27: 512 | B27: 9 | C27: ='01_核心常量'!$D$20*LOG(A27/$B$5,2)*'01_核心常量'!$D$12 | D27: 超载 | E27: 2★ | F27: 3.5 | G27: ='01_核心常量'!$D$21*F27*'01_核心常量'!$D$22 | H27: =A27/$B$5 | I27: =IF(A27>='01_核心常量'!$D$29,A27/$B$5*'01_核心常量'!$D$28,0) | J27: =H27*'01_核心常量'!$D$25 | K27: 3 | L27: =H27*'01_核心常量'!$D$26 | M27: =H27*'01_核心常量'!$D$27
A28: 1024 | B28: 10 | C28: ='01_核心常量'!$D$20*LOG(A28/$B$5,2)*'01_核心常量'!$D$12 | D28: 超载 | E28: 3★ | F28: 6 | G28: ='01_核心常量'!$D$21*F28*'01_核心常量'!$D$22 | H28: =A28/$B$5 | I28: =IF(A28>='01_核心常量'!$D$29,A28/$B$5*'01_核心常量'!$D$28,0) | J28: =H28*'01_核心常量'!$D$25 | K28: 3 | L28: =H28*'01_核心常量'!$D$26 | M28: =H28*'01_核心常量'!$D$27
A29: 2048 | B29: 11 | C29: ='01_核心常量'!$D$20*LOG(A29/$B$5,2)*'01_核心常量'!$D$12 | D29: 超载 | E29: 4★ | F29: 10 | G29: ='01_核心常量'!$D$21*F29*'01_核心常量'!$D$22 | H29: =A29/$B$5 | I29: =IF(A29>='01_核心常量'!$D$29,A29/$B$5*'01_核心常量'!$D$28,0) | J29: =H29*'01_核心常量'!$D$25 | K29: 8 | L29: =H29*'01_核心常量'!$D$26 | M29: =H29*'01_核心常量'!$D$27
A30: 4096 | B30: 12 | C30: ='01_核心常量'!$D$20*LOG(A30/$B$5,2)*'01_核心常量'!$D$12 | D30: 超载 | E30: 5★ | F30: 16 | G30: ='01_核心常量'!$D$21*F30*'01_核心常量'!$D$22 | H30: =A30/$B$5 | I30: =IF(A30>='01_核心常量'!$D$29,A30/$B$5*'01_核心常量'!$D$28,0) | J30: =H30*'01_核心常量'!$D$25 | K30: 8 | L30: =H30*'01_核心常量'!$D$26 | M30: =H30*'01_核心常量'!$D$27
A31: 8192 | B31: 13 | C31: ='01_核心常量'!$D$20*LOG(A31/$B$5,2)*'01_核心常量'!$D$12 | D31: — | E31: — | F31: 1 | G31: ='01_核心常量'!$D$21*F31*'01_核心常量'!$D$22 | H31: =A31/$B$5 | I31: =IF(A31>='01_核心常量'!$D$29,A31/$B$5*'01_核心常量'!$D$28,0) | J31: =H31*'01_核心常量'!$D$25 | K31: 8 | L31: =H31*'01_核心常量'!$D$26 | M31: =H31*'01_核心常量'!$D$27
A33: ★ 附魔总伤害池 = EP x 威力系数 x ELEM_CAP。这是「全场总伤害」，不是单体伤害 —— 火会均分给所有敌人，雷会集中在最前排。两者总量相等，区别纯化为分摊 vs 集中。
A34: ★ 充能' 公式里的 LOG_CORR = 0.78 是实测的 Jensen 修正项。合成值分布右偏，E[log] < log(E[·])，直接用 log(均值) 会高估充能约 28%。
A35: 设计校验：一次 2048 超载（4★）= 180 x 10 x 2.5 = 4,500 总伤害，是关 1 波 1 全波敌人总 HP（570）的 7.9 倍。这是玩家截图分享的 jackpot 时刻。
A37: 共鸣倍率（连续同元素触发）
A38: 连续次数 | B38: 威力加成 | C38: 等效总伤害池 | D38: 说明
A39: 1 | B39: 1 | C39: ='01_核心常量'!$D$21*B39*'01_核心常量'!$D$22 | D39: 首次触发，基准。
A40: 2 | B40: ='01_核心常量'!$D$23 | C40: ='01_核心常量'!$D$21*B40*'01_核心常量'!$D$22 | D40: 轮盘排 [X,X] 的收益。
A41: 3+ | B41: ='01_核心常量'!$D$24 | C41: ='01_核心常量'!$D$21*B41*'01_核心常量'!$D$22 | D41: 附带「元素余韵」：持续类效果时长 +50%。轮盘排 [X,X,X] 是爆发构筑核心。

Sheet 03_波次节奏模型
A1: 波次节奏模型 —— 归一化后 CV'/波 应跨档位恒定（★ 这是 M1 的验收标准）
A3: 关卡 | B3: 生成池 | C3: E[生成] | D3: 平均合成值 | E3: 每波步数 | F3: 合成次数/波 | G3: CV'/波 | H3: 充能'/波 | I3: 小附魔/波 | J3: 星核/波 | K3: 金币/波 | L3: 碎片/波 | M3: 目标校验
A4: 1 | B4: 2(90%)/4(10%) | C4: ='01_核心常量'!$D$13 | D4: =C4*'01_核心常量'!$D$11 | E4: ='01_核心常量'!$D$30/'01_核心常量'!$D$8+'01_核心常量'!$D$9 | F4: =E4*'01_核心常量'!$D$10 | G4: =F4*'01_核心常量'!$D$11 | H4: =F4*'01_核心常量'!$D$20*LOG('01_核心常量'!$D$11,2)*'01_核心常量'!$D$12 | I4: =H4/'01_核心常量'!$D$19 | J4: =G4*'01_核心常量'!$D$25 | K4: =G4*'01_核心常量'!$D$26*(1+'01_核心常量'!$D$38*(A4-1)) | L4: =G4*'01_核心常量'!$D$27*(1+'01_核心常量'!$D$38*(A4-1)) | M4: CV' 应恒定 ≈ 151；小附魔 ≈ 1.5
A5: 2 | B5: 2(70%)/4(20%)/8(10%) | C5: ='01_核心常量'!$D$14 | D5: =C5*'01_核心常量'!$D$11 | E5: ='01_核心常量'!$D$30/'01_核心常量'!$D$8+'01_核心常量'!$D$9 | F5: =E5*'01_核心常量'!$D$10 | G5: =F5*'01_核心常量'!$D$11 | H5: =F5*'01_核心常量'!$D$20*LOG('01_核心常量'!$D$11,2)*'01_核心常量'!$D$12 | I5: =H5/'01_核心常量'!$D$19 | J5: =G5*'01_核心常量'!$D$25 | K5: =G5*'01_核心常量'!$D$26*(1+'01_核心常量'!$D$38*(A5-1)) | L5: =G5*'01_核心常量'!$D$27*(1+'01_核心常量'!$D$38*(A5-1)) | M5: CV' 应恒定 ≈ 151；小附魔 ≈ 1.5
A6: 3 | B6: 2(70%)/4(20%)/8(10%) | C6: ='01_核心常量'!$D$14 | D6: =C6*'01_核心常量'!$D$11 | E6: ='01_核心常量'!$D$30/'01_核心常量'!$D$8+'01_核心常量'!$D$9 | F6: =E6*'01_核心常量'!$D$10 | G6: =F6*'01_核心常量'!$D$11 | H6: =F6*'01_核心常量'!$D$20*LOG('01_核心常量'!$D$11,2)*'01_核心常量'!$D$12 | I6: =H6/'01_核心常量'!$D$19 | J6: =G6*'01_核心常量'!$D$25 | K6: =G6*'01_核心常量'!$D$26*(1+'01_核心常量'!$D$38*(A6-1)) | L6: =G6*'01_核心常量'!$D$27*(1+'01_核心常量'!$D$38*(A6-1)) | M6: CV' 应恒定 ≈ 151；小附魔 ≈ 1.5
A7: 4 | B7: 4(80%)/8(20%) | C7: ='01_核心常量'!$D$15 | D7: =C7*'01_核心常量'!$D$11 | E7: ='01_核心常量'!$D$30/'01_核心常量'!$D$8+'01_核心常量'!$D$9 | F7: =E7*'01_核心常量'!$D$10 | G7: =F7*'01_核心常量'!$D$11 | H7: =F7*'01_核心常量'!$D$20*LOG('01_核心常量'!$D$11,2)*'01_核心常量'!$D$12 | I7: =H7/'01_核心常量'!$D$19 | J7: =G7*'01_核心常量'!$D$25 | K7: =G7*'01_核心常量'!$D$26*(1+'01_核心常量'!$D$38*(A7-1)) | L7: =G7*'01_核心常量'!$D$27*(1+'01_核心常量'!$D$38*(A7-1)) | M7: CV' 应恒定 ≈ 151；小附魔 ≈ 1.5
A8: 5 | B8: 4(80%)/8(20%) | C8: ='01_核心常量'!$D$15 | D8: =C8*'01_核心常量'!$D$11 | E8: ='01_核心常量'!$D$30/'01_核心常量'!$D$8+'01_核心常量'!$D$9 | F8: =E8*'01_核心常量'!$D$10 | G8: =F8*'01_核心常量'!$D$11 | H8: =F8*'01_核心常量'!$D$20*LOG('01_核心常量'!$D$11,2)*'01_核心常量'!$D$12 | I8: =H8/'01_核心常量'!$D$19 | J8: =G8*'01_核心常量'!$D$25 | K8: =G8*'01_核心常量'!$D$26*(1+'01_核心常量'!$D$38*(A8-1)) | L8: =G8*'01_核心常量'!$D$27*(1+'01_核心常量'!$D$38*(A8-1)) | M8: CV' 应恒定 ≈ 151；小附魔 ≈ 1.5
A9: 6 | B9: 4(70%)/8(20%)/16(10%) | C9: ='01_核心常量'!$D$16 | D9: =C9*'01_核心常量'!$D$11 | E9: ='01_核心常量'!$D$30/'01_核心常量'!$D$8+'01_核心常量'!$D$9 | F9: =E9*'01_核心常量'!$D$10 | G9: =F9*'01_核心常量'!$D$11 | H9: =F9*'01_核心常量'!$D$20*LOG('01_核心常量'!$D$11,2)*'01_核心常量'!$D$12 | I9: =H9/'01_核心常量'!$D$19 | J9: =G9*'01_核心常量'!$D$25 | K9: =G9*'01_核心常量'!$D$26*(1+'01_核心常量'!$D$38*(A9-1)) | L9: =G9*'01_核心常量'!$D$27*(1+'01_核心常量'!$D$38*(A9-1)) | M9: CV' 应恒定 ≈ 151；小附魔 ≈ 1.5
A10: 7 | B10: 4(70%)/8(20%)/16(10%) | C10: ='01_核心常量'!$D$16 | D10: =C10*'01_核心常量'!$D$11 | E10: ='01_核心常量'!$D$30/'01_核心常量'!$D$8+'01_核心常量'!$D$9 | F10: =E10*'01_核心常量'!$D$10 | G10: =F10*'01_核心常量'!$D$11 | H10: =F10*'01_核心常量'!$D$20*LOG('01_核心常量'!$D$11,2)*'01_核心常量'!$D$12 | I10: =H10/'01_核心常量'!$D$19 | J10: =G10*'01_核心常量'!$D$25 | K10: =G10*'01_核心常量'!$D$26*(1+'01_核心常量'!$D$38*(A10-1)) | L10: =G10*'01_核心常量'!$D$27*(1+'01_核心常量'!$D$38*(A10-1)) | M10: CV' 应恒定 ≈ 151；小附魔 ≈ 1.5
A11: 8 | B11: 4(70%)/8(20%)/16(10%) | C11: ='01_核心常量'!$D$16 | D11: =C11*'01_核心常量'!$D$11 | E11: ='01_核心常量'!$D$30/'01_核心常量'!$D$8+'01_核心常量'!$D$9 | F11: =E11*'01_核心常量'!$D$10 | G11: =F11*'01_核心常量'!$D$11 | H11: =F11*'01_核心常量'!$D$20*LOG('01_核心常量'!$D$11,2)*'01_核心常量'!$D$12 | I11: =H11/'01_核心常量'!$D$19 | J11: =G11*'01_核心常量'!$D$25 | K11: =G11*'01_核心常量'!$D$26*(1+'01_核心常量'!$D$38*(A11-1)) | L11: =G11*'01_核心常量'!$D$27*(1+'01_核心常量'!$D$38*(A11-1)) | M11: CV' 应恒定 ≈ 151；小附魔 ≈ 1.5
A12: 9 | B12: 8(80%)/16(20%) | C12: ='01_核心常量'!$D$17 | D12: =C12*'01_核心常量'!$D$11 | E12: ='01_核心常量'!$D$30/'01_核心常量'!$D$8+'01_核心常量'!$D$9 | F12: =E12*'01_核心常量'!$D$10 | G12: =F12*'01_核心常量'!$D$11 | H12: =F12*'01_核心常量'!$D$20*LOG('01_核心常量'!$D$11,2)*'01_核心常量'!$D$12 | I12: =H12/'01_核心常量'!$D$19 | J12: =G12*'01_核心常量'!$D$25 | K12: =G12*'01_核心常量'!$D$26*(1+'01_核心常量'!$D$38*(A12-1)) | L12: =G12*'01_核心常量'!$D$27*(1+'01_核心常量'!$D$38*(A12-1)) | M12: CV' 应恒定 ≈ 151；小附魔 ≈ 1.5
A13: 10 | B13: 8(80%)/16(20%) | C13: ='01_核心常量'!$D$17 | D13: =C13*'01_核心常量'!$D$11 | E13: ='01_核心常量'!$D$30/'01_核心常量'!$D$8+'01_核心常量'!$D$9 | F13: =E13*'01_核心常量'!$D$10 | G13: =F13*'01_核心常量'!$D$11 | H13: =F13*'01_核心常量'!$D$20*LOG('01_核心常量'!$D$11,2)*'01_核心常量'!$D$12 | I13: =H13/'01_核心常量'!$D$19 | J13: =G13*'01_核心常量'!$D$25 | K13: =G13*'01_核心常量'!$D$26*(1+'01_核心常量'!$D$38*(A13-1)) | L13: =G13*'01_核心常量'!$D$27*(1+'01_核心常量'!$D$38*(A13-1)) | M13: CV' 应恒定 ≈ 151；小附魔 ≈ 1.5
A14: 12 | B14: 8(80%)/16(20%) | C14: ='01_核心常量'!$D$17 | D14: =C14*'01_核心常量'!$D$11 | E14: ='01_核心常量'!$D$30/'01_核心常量'!$D$8+'01_核心常量'!$D$9 | F14: =E14*'01_核心常量'!$D$10 | G14: =F14*'01_核心常量'!$D$11 | H14: =F14*'01_核心常量'!$D$20*LOG('01_核心常量'!$D$11,2)*'01_核心常量'!$D$12 | I14: =H14/'01_核心常量'!$D$19 | J14: =G14*'01_核心常量'!$D$25 | K14: =G14*'01_核心常量'!$D$26*(1+'01_核心常量'!$D$38*(A14-1)) | L14: =G14*'01_核心常量'!$D$27*(1+'01_核心常量'!$D$38*(A14-1)) | M14: CV' 应恒定 ≈ 151；小附魔 ≈ 1.5
A15: 15 | B15: 8(80%)/16(20%) | C15: ='01_核心常量'!$D$17 | D15: =C15*'01_核心常量'!$D$11 | E15: ='01_核心常量'!$D$30/'01_核心常量'!$D$8+'01_核心常量'!$D$9 | F15: =E15*'01_核心常量'!$D$10 | G15: =F15*'01_核心常量'!$D$11 | H15: =F15*'01_核心常量'!$D$20*LOG('01_核心常量'!$D$11,2)*'01_核心常量'!$D$12 | I15: =H15/'01_核心常量'!$D$19 | J15: =G15*'01_核心常量'!$D$25 | K15: =G15*'01_核心常量'!$D$26*(1+'01_核心常量'!$D$38*(A15-1)) | L15: =G15*'01_核心常量'!$D$27*(1+'01_核心常量'!$D$38*(A15-1)) | M15: CV' 应恒定 ≈ 151；小附魔 ≈ 1.5
A17: ★★【M1 验收标准】CV'/波 与 小附魔/波 两列必须跨档位基本恒定。若出现随关卡单调上升，说明归一化失效，下游经济会重新膨胀。
A18: 【对照 v0.1】未归一化时 CV/波 从 299 涨到 5,031（17 倍），星核从 25 涨到 604 —— 后期每波能放 40 次战术指令，战斗压力彻底失效。
A19: ★【最根本的认知】2048 的合成产出是守恒量：每步生成 1 个方块，稳态必然消耗约 0.90 个（实测 0.89–0.94，跨策略差异 <6%）。所以总 CV ≈ 步数 x 生成值 x 常数，与技术水平无关。任何建立在「合成频率 / 合成总量」上的技巧表达都是无效的。
A20: ★【推论】技巧只能挂在「大数字达成率」上。小附魔频率实测 random 1.87 / greedy 1.99，仅差 6%；而 P(2048) 是 1.3% vs 48%。这就是为什么小附魔必须降频给超载让路。
A21: 【设计意图】星核/波 目标 20–30，即每波约 0.9 次战术指令。若超过 50，说明玩家能靠指令无限续命，战斗压力失效。

Sheet 04_关卡与敌人
A1: 关卡缩放 —— 敌人强度 vs 玩家战力成长（★ v0.2 换用大数字达成率驱动的技术模型）
A3: 关卡 n | B3: 敌人HP倍率 | C3: 敌人伤害倍率 | D3: 敌人速度倍率 | E3: 关卡收益倍率 | F3: 玩家战力倍率 | G3: 余量比 | H3: 状态 | I3: 第5波敌人总HP(估) | J3: 玩家DPS(估)
A4: 1 | B4: ='01_核心常量'!$D$32^(A4-1)*(1+'01_核心常量'!$D$33*(A4-1)) | C4: ='01_核心常量'!$D$37^(A4-1) | D4: =1+'01_核心常量'!$D$36*(A4-1) | E4: 1 | F4: 1 | G4: =F4/B4 | H4: =IF(G4>1.15,"轻松",IF(G4>0.85,"势均力敌",IF(G4>0.6,"吃力","撞墙"))) | I4: =4330*B4 | J4: =('01_核心常量'!$D$44*'01_核心常量'!$D$46*'01_核心常量'!$D$45)*F4
A5: 2 | B5: ='01_核心常量'!$D$32^(A5-1)*(1+'01_核心常量'!$D$33*(A5-1)) | C5: ='01_核心常量'!$D$37^(A5-1) | D5: =1+'01_核心常量'!$D$36*(A5-1) | E5: =E4+'01_核心常量'!$D$38+0.1*(A5-2) | F5: =F4*(1+'01_核心常量'!$D$42*'01_核心常量'!$D$43^(A5-2))^'01_核心常量'!$D$41 | G5: =F5/B5 | H5: =IF(G5>1.15,"轻松",IF(G5>0.85,"势均力敌",IF(G5>0.6,"吃力","撞墙"))) | I5: =4330*B5 | J5: =('01_核心常量'!$D$44*'01_核心常量'!$D$46*'01_核心常量'!$D$45)*F5
A6: 3 | B6: ='01_核心常量'!$D$32^(A6-1)*(1+'01_核心常量'!$D$33*(A6-1)) | C6: ='01_核心常量'!$D$37^(A6-1) | D6: =1+'01_核心常量'!$D$36*(A6-1) | E6: =E5+'01_核心常量'!$D$38+0.1*(A6-2) | F6: =F5*(1+'01_核心常量'!$D$42*'01_核心常量'!$D$43^(A6-2))^'01_核心常量'!$D$41 | G6: =F6/B6 | H6: =IF(G6>1.15,"轻松",IF(G6>0.85,"势均力敌",IF(G6>0.6,"吃力","撞墙"))) | I6: =4330*B6 | J6: =('01_核心常量'!$D$44*'01_核心常量'!$D$46*'01_核心常量'!$D$45)*F6
A7: 4 | B7: ='01_核心常量'!$D$32^(A7-1)*(1+'01_核心常量'!$D$33*(A7-1)) | C7: ='01_核心常量'!$D$37^(A7-1) | D7: =1+'01_核心常量'!$D$36*(A7-1) | E7: =E6+'01_核心常量'!$D$38+0.1*(A7-2) | F7: =F6*(1+'01_核心常量'!$D$42*'01_核心常量'!$D$43^(A7-2))^'01_核心常量'!$D$41 | G7: =F7/B7 | H7: =IF(G7>1.15,"轻松",IF(G7>0.85,"势均力敌",IF(G7>0.6,"吃力","撞墙"))) | I7: =4330*B7 | J7: =('01_核心常量'!$D$44*'01_核心常量'!$D$46*'01_核心常量'!$D$45)*F7
A8: 5 | B8: ='01_核心常量'!$D$32^(A8-1)*(1+'01_核心常量'!$D$33*(A8-1)) | C8: ='01_核心常量'!$D$37^(A8-1) | D8: =1+'01_核心常量'!$D$36*(A8-1) | E8: =E7+'01_核心常量'!$D$38+0.1*(A8-2) | F8: =F7*(1+'01_核心常量'!$D$42*'01_核心常量'!$D$43^(A8-2))^'01_核心常量'!$D$41 | G8: =F8/B8 | H8: =IF(G8>1.15,"轻松",IF(G8>0.85,"势均力敌",IF(G8>0.6,"吃力","撞墙"))) | I8: =4330*B8 | J8: =('01_核心常量'!$D$44*'01_核心常量'!$D$46*'01_核心常量'!$D$45)*F8
A9: 6 | B9: ='01_核心常量'!$D$32^(A9-1)*(1+'01_核心常量'!$D$33*(A9-1)) | C9: ='01_核心常量'!$D$37^(A9-1) | D9: =1+'01_核心常量'!$D$36*(A9-1) | E9: =E8+'01_核心常量'!$D$38+0.1*(A9-2) | F9: =F8*(1+'01_核心常量'!$D$42*'01_核心常量'!$D$43^(A9-2))^'01_核心常量'!$D$41 | G9: =F9/B9 | H9: =IF(G9>1.15,"轻松",IF(G9>0.85,"势均力敌",IF(G9>0.6,"吃力","撞墙"))) | I9: =4330*B9 | J9: =('01_核心常量'!$D$44*'01_核心常量'!$D$46*'01_核心常量'!$D$45)*F9
A10: 7 | B10: ='01_核心常量'!$D$32^(A10-1)*(1+'01_核心常量'!$D$33*(A10-1)) | C10: ='01_核心常量'!$D$37^(A10-1) | D10: =1+'01_核心常量'!$D$36*(A10-1) | E10: =E9+'01_核心常量'!$D$38+0.1*(A10-2) | F10: =F9*(1+'01_核心常量'!$D$42*'01_核心常量'!$D$43^(A10-2))^'01_核心常量'!$D$41 | G10: =F10/B10 | H10: =IF(G10>1.15,"轻松",IF(G10>0.85,"势均力敌",IF(G10>0.6,"吃力","撞墙"))) | I10: =4330*B10 | J10: =('01_核心常量'!$D$44*'01_核心常量'!$D$46*'01_核心常量'!$D$45)*F10
A11: 8 | B11: ='01_核心常量'!$D$32^(A11-1)*(1+'01_核心常量'!$D$33*(A11-1)) | C11: ='01_核心常量'!$D$37^(A11-1) | D11: =1+'01_核心常量'!$D$36*(A11-1) | E11: =E10+'01_核心常量'!$D$38+0.1*(A11-2) | F11: =F10*(1+'01_核心常量'!$D$42*'01_核心常量'!$D$43^(A11-2))^'01_核心常量'!$D$41 | G11: =F11/B11 | H11: =IF(G11>1.15,"轻松",IF(G11>0.85,"势均力敌",IF(G11>0.6,"吃力","撞墙"))) | I11: =4330*B11 | J11: =('01_核心常量'!$D$44*'01_核心常量'!$D$46*'01_核心常量'!$D$45)*F11
A12: 9 | B12: ='01_核心常量'!$D$32^(A12-1)*(1+'01_核心常量'!$D$33*(A12-1)) | C12: ='01_核心常量'!$D$37^(A12-1) | D12: =1+'01_核心常量'!$D$36*(A12-1) | E12: =E11+'01_核心常量'!$D$38+0.1*(A12-2) | F12: =F11*(1+'01_核心常量'!$D$42*'01_核心常量'!$D$43^(A12-2))^'01_核心常量'!$D$41 | G12: =F12/B12 | H12: =IF(G12>1.15,"轻松",IF(G12>0.85,"势均力敌",IF(G12>0.6,"吃力","撞墙"))) | I12: =4330*B12 | J12: =('01_核心常量'!$D$44*'01_核心常量'!$D$46*'01_核心常量'!$D$45)*F12
A13: 10 | B13: ='01_核心常量'!$D$32^(A13-1)*(1+'01_核心常量'!$D$33*(A13-1)) | C13: ='01_核心常量'!$D$37^(A13-1) | D13: =1+'01_核心常量'!$D$36*(A13-1) | E13: =E12+'01_核心常量'!$D$38+0.1*(A13-2) | F13: =F12*(1+'01_核心常量'!$D$42*'01_核心常量'!$D$43^(A13-2))^'01_核心常量'!$D$41 | G13: =F13/B13 | H13: =IF(G13>1.15,"轻松",IF(G13>0.85,"势均力敌",IF(G13>0.6,"吃力","撞墙"))) | I13: =4330*B13 | J13: =('01_核心常量'!$D$44*'01_核心常量'!$D$46*'01_核心常量'!$D$45)*F13
A14: 11 | B14: ='01_核心常量'!$D$32^(A14-1)*(1+'01_核心常量'!$D$33*(A14-1)) | C14: ='01_核心常量'!$D$37^(A14-1) | D14: =1+'01_核心常量'!$D$36*(A14-1) | E14: =E13+'01_核心常量'!$D$38+0.1*(A14-2) | F14: =F13*(1+'01_核心常量'!$D$42*'01_核心常量'!$D$43^(A14-2))^'01_核心常量'!$D$41 | G14: =F14/B14 | H14: =IF(G14>1.15,"轻松",IF(G14>0.85,"势均力敌",IF(G14>0.6,"吃力","撞墙"))) | I14: =4330*B14 | J14: =('01_核心常量'!$D$44*'01_核心常量'!$D$46*'01_核心常量'!$D$45)*F14
A15: 12 | B15: ='01_核心常量'!$D$32^(A15-1)*(1+'01_核心常量'!$D$33*(A15-1)) | C15: ='01_核心常量'!$D$37^(A15-1) | D15: =1+'01_核心常量'!$D$36*(A15-1) | E15: =E14+'01_核心常量'!$D$38+0.1*(A15-2) | F15: =F14*(1+'01_核心常量'!$D$42*'01_核心常量'!$D$43^(A15-2))^'01_核心常量'!$D$41 | G15: =F15/B15 | H15: =IF(G15>1.15,"轻松",IF(G15>0.85,"势均力敌",IF(G15>0.6,"吃力","撞墙"))) | I15: =4330*B15 | J15: =('01_核心常量'!$D$44*'01_核心常量'!$D$46*'01_核心常量'!$D$45)*F15
A16: 13 | B16: ='01_核心常量'!$D$32^(A16-1)*(1+'01_核心常量'!$D$33*(A16-1)) | C16: ='01_核心常量'!$D$37^(A16-1) | D16: =1+'01_核心常量'!$D$36*(A16-1) | E16: =E15+'01_核心常量'!$D$38+0.1*(A16-2) | F16: =F15*(1+'01_核心常量'!$D$42*'01_核心常量'!$D$43^(A16-2))^'01_核心常量'!$D$41 | G16: =F16/B16 | H16: =IF(G16>1.15,"轻松",IF(G16>0.85,"势均力敌",IF(G16>0.6,"吃力","撞墙"))) | I16: =4330*B16 | J16: =('01_核心常量'!$D$44*'01_核心常量'!$D$46*'01_核心常量'!$D$45)*F16
... A18: 15 | B18: ='01_核心常量'!$D$32^(A18-1)*(1+'01_核心常量'!$D$33*(A18-1)) | C18: ='01_核心常量'!$D$37^(A18-1) | D18: =1+'01_核心常量'!$D$36*(A18-1) | E18: =E17+'01_核心常量'!$D$38+0.1*(A18-2) | F18: =F17*(1+'01_核心常量'!$D$42*'01_核心常量'!$D$43^(A18-2))^'01_核心常量'!$D$41 | G18: =F18/B18 | H18: =IF(G18>1.15,"轻松",IF(G18>0.85,"势均力敌",IF(G18>0.6,"吃力","撞墙"))) | I18: =4330*B18 | J18: =('01_核心常量'!$D$44*'01_核心常量'!$D$46*'01_核心常量'!$D$45)*F18
A20: 【余量比判读】>1.15 轻松 / 0.85–1.15 势均力敌 / 0.6–0.85 吃力 / <0.6 撞墙。
A21: ★ 余量比只是 DPS 上限，是乐观估计。玩家真正的死因不是「打不动」，而是「漏过去的敌人把星枢打爆」。必须用下面的漏怪模型判定实际死亡关卡。
A23: 技术系数模型（★ v0.2 重写）
A24: 参数 | B24: 值 | C24: 说明
A25: 新手 技术系数 | B25: =(1-'01_核心常量'!$D$50)+'01_核心常量'!$D$50*((1-'01_核心常量'!$D$51)*'01_核心常量'!$D$55+'01_核心常量'!$D$51*'01_核心常量'!$D$52) | C25: 超载次数比 0.33（random 策略实测）
A26: 中等 技术系数 | B26: =(1-'01_核心常量'!$D$50)+'01_核心常量'!$D$50*((1-'01_核心常量'!$D$51)*'01_核心常量'!$D$55+'01_核心常量'!$D$51*'01_核心常量'!$D$53) | C26: 超载次数比 0.60
A27: 高手 技术系数 | B27: =(1-'01_核心常量'!$D$50)+'01_核心常量'!$D$50*((1-'01_核心常量'!$D$51)*'01_核心常量'!$D$55+'01_核心常量'!$D$51*'01_核心常量'!$D$54) | C27: 超载次数比 1.00（基准）
A28: 技术回报（高手 ÷ 新手） | B28: =$B$27/$B$25 | C28: ★ v0.1 假设 1.65x，实测修正后约 1.31x。原因是植物（40%）与小附魔（24%）都不随技术变化，稀释了超载的贡献。
A30: ★【v0.2 文档勘误】GDD v0.2 §1 M3 写的「总技术回报 1.62x」是错的 —— 它把「超载占附魔 60%」误当成「超载占总输出 60%」代入公式。正确值见上表，约 1.31x。
A31: 【技术模型结构】总输出 = 植物 40%（技术无关）+ 小附魔 24%（技术无关，倍率 1.05）+ 超载 36%（技术强相关）。要让技术回报继续上升，只能提高 OVER_SHARE 或 ENCH_SHARE，代价是植物存在感进一步下降。
A33: 漏怪预算模型 —— 真实死亡关卡判定
A34: 逻辑：当余量比 x 技术系数 x 养成系数 < 1 时，缺口比例的敌人会漏过防线；漏怪数 x 敌人伤害 > 星枢 HP 即阵亡。
A35: 关卡 n | B35: 余量比(基准) | C35: 可承受漏怪数 | D35: 新手 | E35: 中等 | F35: 高手 | G35: 满养成高手
A36: 1 | B36: =G4 | C36: ='01_核心常量'!$D$39/('01_核心常量'!$D$35*'01_核心常量'!$D$37^(A36-1)) | D36: =IF('01_核心常量'!$D$34*MAX(0,1-B36*$B$25*1)<C36,"存活","阵亡") | E36: =IF('01_核心常量'!$D$34*MAX(0,1-B36*$B$26*1)<C36,"存活","阵亡") | F36: =IF('01_核心常量'!$D$34*MAX(0,1-B36*$B$27*1)<C36,"存活","阵亡") | G36: =IF('01_核心常量'!$D$34*MAX(0,1-B36*$B$27*'01_核心常量'!$D$58)<C36,"存活","阵亡")
A37: 2 | B37: =G5 | C37: ='01_核心常量'!$D$39/('01_核心常量'!$D$35*'01_核心常量'!$D$37^(A37-1)) | D37: =IF('01_核心常量'!$D$34*MAX(0,1-B37*$B$25*1)<C37,"存活","阵亡") | E37: =IF('01_核心常量'!$D$34*MAX(0,1-B37*$B$26*1)<C37,"存活","阵亡") | F37: =IF('01_核心常量'!$D$34*MAX(0,1-B37*$B$27*1)<C37,"存活","阵亡") | G37: =IF('01_核心常量'!$D$34*MAX(0,1-B37*$B$27*'01_核心常量'!$D$58)<C37,"存活","阵亡")
A38: 3 | B38: =G6 | C38: ='01_核心常量'!$D$39/('01_核心常量'!$D$35*'01_核心常量'!$D$37^(A38-1)) | D38: =IF('01_核心常量'!$D$34*MAX(0,1-B38*$B$25*1)<C38,"存活","阵亡") | E38: =IF('01_核心常量'!$D$34*MAX(0,1-B38*$B$26*1)<C38,"存活","阵亡") | F38: =IF('01_核心常量'!$D$34*MAX(0,1-B38*$B$27*1)<C38,"存活","阵亡") | G38: =IF('01_核心常量'!$D$34*MAX(0,1-B38*$B$27*'01_核心常量'!$D$58)<C38,"存活","阵亡")
A39: 4 | B39: =G7 | C39: ='01_核心常量'!$D$39/('01_核心常量'!$D$35*'01_核心常量'!$D$37^(A39-1)) | D39: =IF('01_核心常量'!$D$34*MAX(0,1-B39*$B$25*1)<C39,"存活","阵亡") | E39: =IF('01_核心常量'!$D$34*MAX(0,1-B39*$B$26*1)<C39,"存活","阵亡") | F39: =IF('01_核心常量'!$D$34*MAX(0,1-B39*$B$27*1)<C39,"存活","阵亡") | G39: =IF('01_核心常量'!$D$34*MAX(0,1-B39*$B$27*'01_核心常量'!$D$58)<C39,"存活","阵亡")
A40: 5 | B40: =G8 | C40: ='01_核心常量'!$D$39/('01_核心常量'!$D$35*'01_核心常量'!$D$37^(A40-1)) | D40: =IF('01_核心常量'!$D$34*MAX(0,1-B40*$B$25*1)<C40,"存活","阵亡") | E40: =IF('01_核心常量'!$D$34*MAX(0,1-B40*$B$26*1)<C40,"存活","阵亡") | F40: =IF('01_核心常量'!$D$34*MAX(0,1-B40*$B$27*1)<C40,"存活","阵亡") | G40: =IF('01_核心常量'!$D$34*MAX(0,1-B40*$B$27*'01_核心常量'!$D$58)<C40,"存活","阵亡")
A41: 6 | B41: =G9 | C41: ='01_核心常量'!$D$39/('01_核心常量'!$D$35*'01_核心常量'!$D$37^(A41-1)) | D41: =IF('01_核心常量'!$D$34*MAX(0,1-B41*$B$25*1)<C41,"存活","阵亡") | E41: =IF('01_核心常量'!$D$34*MAX(0,1-B41*$B$26*1)<C41,"存活","阵亡") | F41: =IF('01_核心常量'!$D$34*MAX(0,1-B41*$B$27*1)<C41,"存活","阵亡") | G41: =IF('01_核心常量'!$D$34*MAX(0,1-B41*$B$27*'01_核心常量'!$D$58)<C41,"存活","阵亡")
A42: 7 | B42: =G10 | C42: ='01_核心常量'!$D$39/('01_核心常量'!$D$35*'01_核心常量'!$D$37^(A42-1)) | D42: =IF('01_核心常量'!$D$34*MAX(0,1-B42*$B$25*1)<C42,"存活","阵亡") | E42: =IF('01_核心常量'!$D$34*MAX(0,1-B42*$B$26*1)<C42,"存活","阵亡") | F42: =IF('01_核心常量'!$D$34*MAX(0,1-B42*$B$27*1)<C42,"存活","阵亡") | G42: =IF('01_核心常量'!$D$34*MAX(0,1-B42*$B$27*'01_核心常量'!$D$58)<C42,"存活","阵亡")
A43: 8 | B43: =G11 | C43: ='01_核心常量'!$D$39/('01_核心常量'!$D$35*'01_核心常量'!$D$37^(A43-1)) | D43: =IF('01_核心常量'!$D$34*MAX(0,1-B43*$B$25*1)<C43,"存活","阵亡") | E43: =IF('01_核心常量'!$D$34*MAX(0,1-B43*$B$26*1)<C43,"存活","阵亡") | F43: =IF('01_核心常量'!$D$34*MAX(0,1-B43*$B$27*1)<C43,"存活","阵亡") | G43: =IF('01_核心常量'!$D$34*MAX(0,1-B43*$B$27*'01_核心常量'!$D$58)<C43,"存活","阵亡")
A44: 9 | B44: =G12 | C44: ='01_核心常量'!$D$39/('01_核心常量'!$D$35*'01_核心常量'!$D$37^(A44-1)) | D44: =IF('01_核心常量'!$D$34*MAX(0,1-B44*$B$25*1)<C44,"存活","阵亡") | E44: =IF('01_核心常量'!$D$34*MAX(0,1-B44*$B$26*1)<C44,"存活","阵亡") | F44: =IF('01_核心常量'!$D$34*MAX(0,1-B44*$B$27*1)<C44,"存活","阵亡") | G44: =IF('01_核心常量'!$D$34*MAX(0,1-B44*$B$27*'01_核心常量'!$D$58)<C44,"存活","阵亡")
A45: 10 | B45: =G13 | C45: ='01_核心常量'!$D$39/('01_核心常量'!$D$35*'01_核心常量'!$D$37^(A45-1)) | D45: =IF('01_核心常量'!$D$34*MAX(0,1-B45*$B$25*1)<C45,"存活","阵亡") | E45: =IF('01_核心常量'!$D$34*MAX(0,1-B45*$B$26*1)<C45,"存活","阵亡") | F45: =IF('01_核心常量'!$D$34*MAX(0,1-B45*$B$27*1)<C45,"存活","阵亡") | G45: =IF('01_核心常量'!$D$34*MAX(0,1-B45*$B$27*'01_核心常量'!$D$58)<C45,"存活","阵亡")
A46: 11 | B46: =G14 | C46: ='01_核心常量'!$D$39/('01_核心常量'!$D$35*'01_核心常量'!$D$37^(A46-1)) | D46: =IF('01_核心常量'!$D$34*MAX(0,1-B46*$B$25*1)<C46,"存活","阵亡") | E46: =IF('01_核心常量'!$D$34*MAX(0,1-B46*$B$26*1)<C46,"存活","阵亡") | F46: =IF('01_核心常量'!$D$34*MAX(0,1-B46*$B$27*1)<C46,"存活","阵亡") | G46: =IF('01_核心常量'!$D$34*MAX(0,1-B46*$B$27*'01_核心常量'!$D$58)<C46,"存活","阵亡")
...

Sheet 05_植物
A1: 植物数值与成长模型（★ v0.2：植物降级为辅助定位，主输出交给附魔）
A2: 成长公式：DPS = 基础 × (1 + 每星DPS加成×(星级−1)) × (1 + 每级DPS加成×(等级−1)) × 养成树枝叶加成
A3: ★ v0.2 变更：基础 DPS 整体下调约 42%（焰心草 12 → 7）。原因：按 v0.1 数值实算，关 1 每波植物输出是附魔的 2.7 倍，玩家不滑棋盘也能赢，直接违反支柱 P2。
A4: 植物 | B4: 元素 | C4: 攻击形态 | D4: 基础DPS | E4: v0.1 旧值 | F4: 射程(格) | G4: 特性 | H4: 大招(4晶核/25s)
A5: 焰心草 | B5: 火 | C5: 直射单体 | D5: 7 | E5: 12 | F5: 3 | G5: 命中附加灼烧：3 秒内每秒 3 伤害 | H5: 全场灼烧 8s，每秒 EP×0.15
A6: 潮汐藤 | B6: 水 | C6: 环形 AoE | D6: 4 | E6: 7 | F6: 1.5 | G6: 范围内敌人 −20% 移速（持续） | H6: 全体击退 2 格 + 减速 50%（4s）
A7: 荆棘木 | B7: 木 | C7: 穿透直线 | D7: 6 | E7: 11 | F7: 无限 | G7: 无视前排阻挡，贯穿本行 | H7: 贯穿全屏光束，EP×3.0
A8: 辉光苔 | B8: 光 | C8: 辅助(无攻击) | D8: 0 | E8: 0 | F8: — | G8: 每 10s：+1 步 或 +8 充能（玩家预设） | H8: 立即 +4 步 +60 充能，全植物攻速 +50%（6s）
A9: 雷鸣花 | B9: 雷 | C9: 溅射 | D9: 6 | E9: 10 | F9: 2.5 | G9: 命中溅射周围 50% 伤害 | H9: 15 次随机落雷，每次 EP×0.4
A10: 霜晶莲 | B10: 冰 | C10: 直射单体 | D10: 5 | E10: 8 | F10: 3 | G10: 命中减速 30%（2s） | H10: 全场冻结 4s，冻结期间受伤 +25%
A12: 星级 / 等级成长曲线（以荆棘木 基础DPS=6 为例）
A13: 等级\星级 | B13: 1★ | C13: 2★ | D13: 3★ | E13: 4★ | F13: 5★
A14: Lv.1 | B14: =6*(1+'01_核心常量'!$D$47*(1-1))*(1+'01_核心常量'!$D$48*(1-1)) | C14: =6*(1+'01_核心常量'!$D$47*(2-1))*(1+'01_核心常量'!$D$48*(1-1)) | D14: =6*(1+'01_核心常量'!$D$47*(3-1))*(1+'01_核心常量'!$D$48*(1-1)) | E14: =6*(1+'01_核心常量'!$D$47*(4-1))*(1+'01_核心常量'!$D$48*(1-1)) | F14: =6*(1+'01_核心常量'!$D$47*(5-1))*(1+'01_核心常量'!$D$48*(1-1))
A15: Lv.10 | B15: =6*(1+'01_核心常量'!$D$47*(1-1))*(1+'01_核心常量'!$D$48*(10-1)) | C15: =6*(1+'01_核心常量'!$D$47*(2-1))*(1+'01_核心常量'!$D$48*(10-1)) | D15: =6*(1+'01_核心常量'!$D$47*(3-1))*(1+'01_核心常量'!$D$48*(10-1)) | E15: =6*(1+'01_核心常量'!$D$47*(4-1))*(1+'01_核心常量'!$D$48*(10-1)) | F15: =6*(1+'01_核心常量'!$D$47*(5-1))*(1+'01_核心常量'!$D$48*(10-1))
A16: Lv.20 | B16: =6*(1+'01_核心常量'!$D$47*(1-1))*(1+'01_核心常量'!$D$48*(20-1)) | C16: =6*(1+'01_核心常量'!$D$47*(2-1))*(1+'01_核心常量'!$D$48*(20-1)) | D16: =6*(1+'01_核心常量'!$D$47*(3-1))*(1+'01_核心常量'!$D$48*(20-1)) | E16: =6*(1+'01_核心常量'!$D$47*(4-1))*(1+'01_核心常量'!$D$48*(20-1)) | F16: =6*(1+'01_核心常量'!$D$47*(5-1))*(1+'01_核心常量'!$D$48*(20-1))
A17: Lv.30 | B17: =6*(1+'01_核心常量'!$D$47*(1-1))*(1+'01_核心常量'!$D$48*(30-1)) | C17: =6*(1+'01_核心常量'!$D$47*(2-1))*(1+'01_核心常量'!$D$48*(30-1)) | D17: =6*(1+'01_核心常量'!$D$47*(3-1))*(1+'01_核心常量'!$D$48*(30-1)) | E17: =6*(1+'01_核心常量'!$D$47*(4-1))*(1+'01_核心常量'!$D$48*(30-1)) | F17: =6*(1+'01_核心常量'!$D$47*(5-1))*(1+'01_核心常量'!$D$48*(30-1))
A18: Lv.40 | B18: =6*(1+'01_核心常量'!$D$47*(1-1))*(1+'01_核心常量'!$D$48*(40-1)) | C18: =6*(1+'01_核心常量'!$D$47*(2-1))*(1+'01_核心常量'!$D$48*(40-1)) | D18: =6*(1+'01_核心常量'!$D$47*(3-1))*(1+'01_核心常量'!$D$48*(40-1)) | E18: =6*(1+'01_核心常量'!$D$47*(4-1))*(1+'01_核心常量'!$D$48*(40-1)) | F18: =6*(1+'01_核心常量'!$D$47*(5-1))*(1+'01_核心常量'!$D$48*(40-1))
A19: Lv.50 | B19: =6*(1+'01_核心常量'!$D$47*(1-1))*(1+'01_核心常量'!$D$48*(50-1)) | C19: =6*(1+'01_核心常量'!$D$47*(2-1))*(1+'01_核心常量'!$D$48*(50-1)) | D19: =6*(1+'01_核心常量'!$D$47*(3-1))*(1+'01_核心常量'!$D$48*(50-1)) | E19: =6*(1+'01_核心常量'!$D$47*(4-1))*(1+'01_核心常量'!$D$48*(50-1)) | F19: =6*(1+'01_核心常量'!$D$47*(5-1))*(1+'01_核心常量'!$D$48*(50-1))
A21: 【设计校验】Lv.50 / 5★ 的荆棘木 = 6 × 1.8 × 1.98 = 21.4 DPS，是初始值的 3.56 倍（倍率不变，只是基数下调）。配合编队位扩展至 6（伙伴位 50% 效率 → ×1.5），植物侧满养成合计约 5.3 倍。
A22: ★★【平衡红线 · 最重要的一个】养成 vs 局内卡牌的战力占比，建议 60 : 40。监控方式：分别统计「满养成 + 零卡牌」与「零养成 + 满卡牌」两种极端配置下的可达关卡，二者之比应落在 1.3 – 1.8 之间。
A24: 六元素效果表 ★ 火的 AoE 已修正（v0.2 M4）
A25: 元素 | B25: 定位 | C25: 总伤害池 | D25: 效果（0★ / EP=180） | E25: 设计意图
A26: 火 | B26: 群体爆发 | C26: ≈EP×2.5 | D26: ★ 全场均分 EP×2.5 总伤害；已灼烧目标 +30% | E26: 清群首选。v0.1 是「每个敌人各受 EP×1.0」= N×EP，13 敌时是雷的 5.2 倍 —— 已封顶修正。
A27: 雷 | B27: 单体爆发 | C27: ≈EP×2.5 | D27: 连锁闪电弹跳 5 次，每次 EP×0.5，优先最前排 | E27: 打 Boss / 重甲。与火总伤害相等，区别纯化为分摊 vs 集中。
A28: 冰 | B28: 控制+增伤 | C28: — | D28: 全场定身 3s，冻结目标受伤 +25% | E28: 救场技，为爆发铺路。进攻向。
A29: 水 | B29: 持续减速 | C29: — | D29: 移速 −40%，持续 5s，造成伤害 −20% | E29: 拖时间，给棋盘争取步数。防守向。
A30: 木 | B30: 己方增益 | C30: — | D30: 植物攻速 +35%，持续 8s；星枢回复 EP×0.2 | E30: 长线收益，配合高 DPS 编队才有价值。
A31: 光 | B31: 资源调度 | C31: — | D31: 清除棋盘所有 ≤4 方块；+2 步；植物伤害 +25%（8s） | E31: 唯一直接强化棋盘的元素，是解卡保底。
A33: ★ 平衡校验：火与雷总伤害池都是 EP × 2.5 = 450（EP=180）。火分摊给全场（对 6 敌每人 75），雷集中在最前排（5 跳 × 90）。场面宽选火，打 Boss 选雷 —— 无绝对优劣。
A35: 元素护盾（让轮盘编排有外部约束）
A36: 护盾类型 | B36: 效果 | C36: 破解方式 | D36: 设计目的
A37: 元素护盾 · X | B37: 受到非 X 元素伤害 −60% | C37: 用 X 元素附魔 / X 属性植物攻击 | D37: 防止玩家把轮盘排成固定最优解。
A38: 元素易伤 · X | B38: 受到 X 元素伤害 +100% | C38: 针对性编排轮盘 | D38: 奖励开局前的配置决策。

Sheet 06_卡牌
A1: 卡池清单 · 稀有度权重 · ★ 战力点等价（v0.2 新增配平工具）
A2: 稀有度权重（按关卡）
A3: 关卡 | B3: 普通 | C3: 稀有 | D3: 史诗 | E3: 传说 | F3: 说明
A4: 1 | B4: 0.7 | C4: 0.25 | D4: 0.05 | E4: 0 | F4: 教学期，几乎只有基础卡。
A5: 2 | B5: 0.6 | C5: 0.3 | D5: 0.09 | E5: 0.01 | F5: 首次见到传说，制造惊喜。
A6: 3 | B6: 0.5 | C6: 0.33 | D6: 0.15 | E6: 0.02 | F6: 构筑开始成型。
A7: 4 | B7: 0.42 | C7: 0.35 | D7: 0.18 | E7: 0.05 | F7: 构筑发力期。
A8: 5+ | B8: 0.35 | C8: 0.35 | D8: 0.22 | E8: 0.08 | F8: 后期。同关第 4、5 波再 +5% 稀有度权重。
A10: 战力点基准（1 战力点 = 关 1 每波 1% 输出 = 11.5 伤害）
A11: 项目 | B11: 每波数值 | C11: 占比 | D11: 说明
A12: 关 1 每波总输出 | B12: 1148 | C12: 100% | D12: 见 10_波次预算表。这是战力点的分母。
A13: 其中 · 附魔 | B13: 675 | C13: 59% | D13: 小附魔 1.5 次 × EP 180 × ELEM_CAP 2.5。
A14: 其中 · 植物 | B14: 473 | C14: 41% | D14: 3 株 × DPS 7 × 30s × HIT_RATE 0.75。
A15: 1 战力点 = | B15: 11.5 | C15: 1% | D15: 所有卡牌效果都折算到这把尺子上。
A17: ★ 合格区间：普通 4–6 点 / 稀有 7–10 点 / 史诗 12–18 点 / 传说 20+ 点。新增卡牌一律先算战力点再定稀有度。
A18: ★ 三条由此得出配平规则：① 步数/充能类卡是最强杠杆（同时放大 CV、充能、超载三条链路），不该出现在普通稀有度；② 经济卡战力点为 0，不该与战斗卡同池竞争，建议独立成池，每波第 3 次三选一固定从经济池抽；③ 战力点 < 2 的卡是废卡，等于卡池缩水。
A20: 卡池（★ 战力点为实测折算，处置列为 v0.2 建议）
A21: 类别 | B21: 卡名 | C21: 稀有度 | D21: 效果 | E21: 战力点 | F21: 处置建议
A22: 棋盘 | B22: 丰饶 | C22: 史诗 | D22: 每次移动额外生成 1 个方块 | E22: 58 | F22: 🔴 破坏性超模（正常卡的 10 倍）。重做或删除。
A23: 棋盘 | B23: 充能加速 | C23: 普通 | D23: 每次合成充能 +25% | E23: 14.7 | F23: 🔴 超模。升为史诗，或削到 +12%。
A24: 棋盘 | B24: 疾风 | C24: 普通 | D24: 步数回复速度 +15% | E24: 8.8 | F24: 🟡 偏强。升为稀有。
A25: 棋盘 | B25: 精准 | C25: 稀有 | D25: 生成值为高档的概率 +25% | E25: 6.5 | F25: ✅ 合格。
A26: 棋盘 | B26: 聚能 | C26: 普通 | D26: 充能条上限 −10 | E26: 6.2 | F26: ✅ 合格（注意：充能降频后此卡价值同步下降）。
A27: 棋盘 | B27: 净化术 | C27: 稀有 | D27: 立即清除所有 ≤8 方块并 +2 步 | E27: 4 | F27: ✅ 情境救急卡。
A28: 棋盘 | B28: 稳健 | C28: 普通 | D28: 步数上限 +1 | E28: 2 | F28: 🔴 近废卡（步数回复才是瓶颈，不是容量）。改为「步数回复 +8%」。
A29: 棋盘 | B29: 连锁核心 | C29: 传说 | D29: 一次移动中第 3 次及以后的合并，充能与 CV 翻倍 | E29: 0.5 | F29: 🔴 废卡且方向错误。实测 random 3连 10.3% > greedy 3.5%，此卡奖励乱滑。删除重做。
A30: 战斗 | B30: 共生 | C30: 传说 | D30: 每个存活植物使全植物伤害 +8% | E30: 9.8 | F30: ✅ 合格（3 株时）；满编队 6 株会超模，建议改为 +5%/株。
A31: 战斗 | B31: 锋锐 | C31: 普通 | D31: 全植物伤害 +15% | E31: 6.2 | F31: ✅ 合格，作为普通卡的战力基准。
A32: 战斗 | B32: 暴击 | C32: 稀有 | D32: 暴击率 +10%，暴击伤害 150% | E32: 5 | F32: ✅ 合格。
A33: 战斗 | B33: 连射 | C33: 普通 | D33: 全植物攻速 +12% | E33: 4.9 | F33: ✅ 合格。
... A51: 战术 | B51: 贪婪核心 | C51: 传说 | D51: 关闭自动升华 | E51: 18 | F51: ✅ 合格。高风险高回报的极限流开关，是升华机制的策略深度所在。
A53: 卡池当前 30 张（含 6 张元素亲和变体则共 35 张）。V2 完整版目标 ≥ 60 张，否则 4–6 关后卡池枯竭，构筑深度崩塌。
A54: 本次查出 4 张需删除/重做（丰饶、连锁核心、稳健、远眺）、2 张需升稀有度（充能加速、疾风）、1 张需降强度（共生）。处理后可用卡池约 26 张，需补充 34 张。
A55: 平衡红线：同名卡重复时效果加法叠加而非乘法，防止指数爆炸。若埋点显示某卡选取率 > 70%，说明该卡超模或同类卡过少。

Sheet 07_风险决策EV
A1: 继续 / 收工 期望值计算器
A2: 公式：收工 EV = P ｜ 继续 EV = p×(P+R) + (1−p)×b×P ｜ 继续优于收工 ⟺ p > (1−b)P / ((1−b)P + R)
A3: 主计算
A4: 参数 | B4: 值 | C4: 说明
A5: 当前累积收益池 P | B5: 1000 | C5: 任意单位。EV 结论与 P 的绝对值无关，只与 R/P 比例有关。
A6: 下一关预期收益 R | B6: =$B$5*'01_核心常量'!$D$57 | C6: R 与 P 成比例（R = P x R_RATIO）。R_RATIO 由关卡收益倍率递增推导。
A7: 失败保底比例 b | B7: ='01_核心常量'!$D$56 | C7: 引用 01 核心常量 B_FAIL。
A8: 玩家自估通关概率 p | B8: 0.6 | C8: 玩家主观判断。设计目标是让临界阈值足够低，从而鼓励冒险。
A10: 指标 | B10: 值 | C10: 说明
A11: 收工 EV | B11: =$B$5 | C11: 确定性收益。
A12: 继续 EV | B12: =$B$8*($B$5+$B$6)+(1-$B$8)*$B$7*$B$5 | C12: p×(P+R) + (1−p)×b×P （b = 保底返还比例）
A13: EV 差值（继续 − 收工） | B13: =$B$12-$B$11 | C13: > 0 表示理性上应该选择继续。
A14: 临界通关概率 p* | B14: =(1-$B$7)*$B$5/((1-$B$7)*$B$5+$B$6) | C14: ★ p > p* 时继续是正期望。这是整个风险系统的核心数字。
A16: 保底比例 b 的敏感性分析（★ 冒险倾向主旋钮）
A17: 保底 b | B17: 临界概率 p* | C17: 玩家行为预测 | D17: 适用产品目标
A18: 0 | B18: =(1-A18)/((1-A18)+'01_核心常量'!$D$57) | C18: 极度保守，玩家会提前收工 | D18: 硬核产品，追求策略纯度
A19: 0.2 | B19: =(1-A19)/((1-A19)+'01_核心常量'!$D$57) | C19: 偏保守，多数玩家 3–4 关收工 | D19: 中核产品，单局时长可控
A20: 0.3 | B20: =(1-A20)/((1-A20)+'01_核心常量'!$D$57) | C20: 略保守 | D20: —
A21: 0.4 | B21: =(1-A21)/((1-A21)+'01_核心常量'!$D$57) | C21: ★ 平衡点，决策有张力 | D21: ★ 推荐：H5 休闲偏中核
A22: 0.5 | B22: =(1-A22)/((1-A22)+'01_核心常量'!$D$57) | C22: 略激进 | D22: —
A23: 0.6 | B23: =(1-A23)/((1-A23)+'01_核心常量'!$D$57) | C23: 激进，玩家几乎不主动收工 | D23: 追求高重开率与广告曝光
A24: 0.8 | B24: =(1-A24)/((1-A24)+'01_核心常量'!$D$57) | C24: 极度激进，收工按钮形同虚设 | D24: 纯广告变现产品
A25: 1 | B25: =(1-A25)/((1-A25)+'01_核心常量'!$D$57) | C25: 无风险，继续永远最优 | D25: 决策消失，不推荐
A27: 【关键洞察】保底比例 b 从 0.2 提到 0.6，临界概率从 50% 降到 33% —— 玩家会明显更爱冒险。这是调节「重开率」最廉价的旋钮，优先用它做 A/B 测。
A28: ★【隐藏的美妙性质】R/P 比例随关卡自然变化：第 2 关约 1.55（p*≈28%，极度鼓励冒险）→ 第 6 关约 0.53（p*≈53%，必须谨慎）。游戏在早期自动怂恿冒进、后期自动转为审慎 —— 这是收益倍率递增结构带来的免费礼物，不要在调参时破坏它。
A29: 【注意】卡牌「备用核心」等价于把 b 临时抬高，会显著改变持有该卡时的决策。它的实际价值远高于描述（战力点 14，但决策价值另计）。
A30: ★【v0.2 商业化约束】广告复活只保留 50% 收益池，不能是 100%。否则玩家把「失败」当正常流程，43% 的临界概率会失效，继续/收工的张力消失。
A31: 【UI 强制要求】关卡结算界面必须同屏显示：当前池 / 下一关倍率与威胁等级 / 继续的预估收益 +R / 失败保底规则 / ★新增：当前棋盘缩略图 + 升华按钮（因为棋盘跨关保留，玩家必须看到自己携带的资产）。

Sheet 08_养成与花园
A1: 星尘养成树与花园产出模型
A2: 养成树成本模型
A3: 成本公式：Cost(n) = 基础成本 × 增长系数^(n−1)
A4: 等级 | B4: 单级成本(星尘) | C4: 累计成本 | D4: 根系效果 | E4: 枝叶效果 | F4: 花蕾效果 | G4: 果实效果
A5: 1 | B5: =ROUND('01_核心常量'!$D$59*'01_核心常量'!$D$60^(A5-1),0) | C5: =B5 | D5: 步数+0.2 / 回复+3% / 充能条−2% | E5: 植物伤害+3% / 星枢HP+4% | F5: 全元素威力+4% | G5: 金币+4% / 碎片+6% / 花园产出+5%
A6: 2 | B6: =ROUND('01_核心常量'!$D$59*'01_核心常量'!$D$60^(A6-1),0) | C6: =C5+B6 | D6: 步数+0.2 / 回复+3% / 充能条−2% | E6: 植物伤害+3% / 星枢HP+4% | F6: 全元素威力+4% | G6: 金币+4% / 碎片+6% / 花园产出+5%
A7: 3 | B7: =ROUND('01_核心常量'!$D$59*'01_核心常量'!$D$60^(A7-1),0) | C7: =C6+B7 | D7: 步数+0.2 / 回复+3% / 充能条−2% | E7: 植物伤害+3% / 星枢HP+4% | F7: 全元素威力+4% | G7: 金币+4% / 碎片+6% / 花园产出+5%
A8: 4 | B8: =ROUND('01_核心常量'!$D$59*'01_核心常量'!$D$60^(A8-1),0) | C8: =C7+B8 | D8: 步数+0.2 / 回复+3% / 充能条−2% | E8: 植物伤害+3% / 星枢HP+4% | F8: 全元素威力+4% | G8: 金币+4% / 碎片+6% / 花园产出+5%
A9: 5 | B9: =ROUND('01_核心常量'!$D$59*'01_核心常量'!$D$60^(A9-1),0) | C9: =C8+B9 | D9: 步数+0.2 / 回复+3% / 充能条−2% | E9: 植物伤害+3% / 星枢HP+4% | F9: 全元素威力+4% | G9: 金币+4% / 碎片+6% / 花园产出+5%
A10: 6 | B10: =ROUND('01_核心常量'!$D$59*'01_核心常量'!$D$60^(A10-1),0) | C10: =C9+B10 | D10: 步数+0.2 / 回复+3% / 充能条−2% | E10: 植物伤害+3% / 星枢HP+4% | F10: 全元素威力+4% | G10: 金币+4% / 碎片+6% / 花园产出+5%
A11: 7 | B11: =ROUND('01_核心常量'!$D$59*'01_核心常量'!$D$60^(A11-1),0) | C11: =C10+B11 | D11: 步数+0.2 / 回复+3% / 充能条−2% | E11: 植物伤害+3% / 星枢HP+4% | F11: 全元素威力+4% | G11: 金币+4% / 碎片+6% / 花园产出+5%
A12: 8 | B12: =ROUND('01_核心常量'!$D$59*'01_核心常量'!$D$60^(A12-1),0) | C12: =C11+B12 | D12: 步数+0.2 / 回复+3% / 充能条−2% | E12: 植物伤害+3% / 星枢HP+4% | F12: 全元素威力+4% | G12: 金币+4% / 碎片+6% / 花园产出+5%
A13: 9 | B13: =ROUND('01_核心常量'!$D$59*'01_核心常量'!$D$60^(A13-1),0) | C13: =C12+B13 | D13: 步数+0.2 / 回复+3% / 充能条−2% | E13: 植物伤害+3% / 星枢HP+4% | F13: 全元素威力+4% | G13: 金币+4% / 碎片+6% / 花园产出+5%
A14: 10 | B14: =ROUND('01_核心常量'!$D$59*'01_核心常量'!$D$60^(A14-1),0) | C14: =C13+B14 | D14: 步数+0.2 / 回复+3% / 充能条−2% | E14: 植物伤害+3% / 星枢HP+4% | F14: 全元素威力+4% | G14: 金币+4% / 碎片+6% / 花园产出+5%
A15: 满级合计 | C15: =SUM(B5:B14)*4 | D15: 4 分支 × 单分支累计
A17: 【当前配置】基础 40 / 增长 1.30 → 单分支满级约 1,705 星尘，全树约 6,820 星尘。早期花园产出 200–500/天，后期 2,000+/天 → 约 3–5 周长线目标。
A18: 【调参方向】H5 休闲产品建议长线不超过 4 周。若超长，把增长系数降到 1.25（全树约 5,300）；若希望更长线支撑赛季，升到 1.35。
A20: 花园产出模型
A21: 稀有度 | B21: 星尘/小时(基) | C21: 30min | D21: 2h | E21: 6h | F21: 6 盆全传说/6h
A22: 普通 | B22: 8 | C22: =B22*0.5 | D22: =B22*2 | E22: =B22*6 | F22: =B22*6*6
A23: 稀有 | B23: 15 | C23: =B23*0.5 | D23: =B23*2 | E23: =B23*6 | F23: =B23*6*6
A24: 史诗 | B24: 28 | C24: =B24*0.5 | D24: =B24*2 | E24: =B24*6 | F24: =B24*6*6
A25: 传说 | B25: 50 | C25: =B25*0.5 | D25: =B25*2 | E25: =B25*6 | F25: =B25*6*6
A27: 产出速率 = 稀有度基础 × (1 + 星级×0.1) × (1 + 养成树果实分支等级×0.05)
A28: 离线计时上限 12 小时（防纯挂机，同时保证次日回归有收益 → 这是次留的核心钩子）。
A29: 花盆：初始 2，最多 6。金币解锁成本 5,000 / 20,000 / 60,000 / 150,000。

Sheet 09_验收清单
A1: 平衡目标与 Broken 判定标准 —— playtest 前必读（v0.2 更新）
A2: 原则：先定义「什么算坏」，才能在 playtest 中认出它。所有阈值在此表预先约定，不做事后解释。
A4: 健康指标（埋点目标）★ 灰色行为 v0.2 修订/新增项
A5: 类别 | B5: 指标 | C5: 目标区间 | D5: 低于下限的处置 | E5: 高于上限的处置
A6: 节奏 | B6: 每波步数消耗 | C6: 25 – 32 步 | D6: 步数回复过快或玩家不积极 → 降低回复速率 | E6: 步数不够用 → 提高回复速率
A7: 节奏 | B7: 每波合成次数 | C7: 25 – 30 次 | D7: 棋盘太挤 → 提升生成分层 | E7: 棋盘过于宽松 → 提升难度
A8: 节奏 | B8: 每波小附魔触发 | C8: 1.2 – 1.8 次 | D8: ★ v0.2 刻意降频（原 3–4）。低于 1.2 → 降 CHARGE_MAX | E8: 高于 1.8 → 升 CHARGE_MAX。注意：频率过高会挤压超载的输出份额， destroys 技术回报
A9: 节奏 | B9: 每波战术指令使用 | C9: 0.8 – 1.5 次 | D9: 星核产出不足 → 提高 K_STAR | E9: 指令续命 → 降低 K_STAR（>2 必须处理）
A10: 难度 | B10: 平均到达关卡 | C10: 4 – 6 关 | D10: 难度过高 → 降低 HP_BASE 至 1.50 | E10: 难度过低 → 升高 HP_BASE 至 1.60
A11: 难度 | B11: 第 1 关失败率 | C11: < 5% | D11: —（达标即可） | E11: 教学波设计失败，需重做波次组成
A12: 难度 | B12: 无养成新手到达 | C12: 4 关 | D12: 新手挫败 → 前 2 关波次时长 +10s | E12: 元游戏无意义 → 前期难度上调
A13: 难度 | B13: 满养成高手到达 | C13: 9 – 11 关 | D13: 长线目标不足 → 提高养成上限 | E13: 养成碾压 → 压缩 STAR_MULT / LV_MULT / SLOT_EFF
A14: 难度 | B14: 收工关卡众数 | C14: 第 4 – 6 关 | D14: 玩家不敢冒险 → 提高保底 b | E14: 玩家不敢收工 → 降低保底 b
A15: 留存 | B15: 单局时长 | C15: 12 – 20 分钟 | D15: 内容不足 → 增加波数 | E15: ★ 疲劳 → 把 WAVE_N 从 5 压到 4（H5 休闲基准是 3–5 分钟）
A16: 健康 | B16: 棋盘卡死触发率 | C16: < 3% | D16: —（达标即可） | E16: 棋盘太小或生成算法有问题，需修伪随机
... A22: ★新版 | B22: 跨关后开局盘面占用 | C22: 关3 <55% / 关5 <70% | D22: —（达标即可） | E22: 过高 → 下调 SUB_TH，或启用「关卡开局半价升华」备用方案
A24: Broken 判定（出现任一症状即为设计失败，需回头改系统而非改数值）
A25: 症状 | B25: 判定阈值 | C25: 根因假设 | D25: 处置
A26: 战斗毫无压力 | B26: 星枢 HP 全损率 < 10% | C26: 敌人推进速度或数量不足 | D26: 提高 SPD_SCL，或在 10 表降低目标余量比
A27: 棋盘被忽略 | B27: 步数常年满仓（余量 > 60%） | C27: 合成收益不足以驱动玩家操作 | D27: 提高 CV 转化系数，或降低 STEP_REGEN
A28: 附魔刷屏 | B28: 每波小附魔 > 2.5 次 | C28: ★ v0.2 阈值下调。充能系数过高 | D28: 降低 CHARGE_K 或升高 CHARGE_MAX
A29: 卡牌无选择 | B29: 某张卡选取率 > 70% | C29: 该卡超模或同类卡过少 | D29: 查 06 表战力点，超 20 点的一律削
A30: 经济通胀 | B30: 金币日增量 / 日消耗 > 3 | C30: 金币汇不足 | D30: 增设金币汇，或降低 K_GOLD
A31: 元素单一最优解 | B31: 某元素使用率 > 50% | C31: 该元素超模，或克制设计未生效 | D31: 调整该元素，或增加对应护盾精英出现率
A32: 后期棋盘饱和 | B32: 第 8 关后棋盘空格 < 3 | C32: 升华阈值过高 | D32: 降低 SUB_TH 至 256，或提高「贪婪核心」出现率
A33: 养成碾压局内 | B33: 满养成 vs 零养成可达关卡比 > 1.8 | C33: 植物星级/等级/编队位成长过大 | D33: 压缩 STAR_MULT / LV_MULT / SLOT_EFF
A34: 局内卡牌无意义 | B34: 满卡牌 vs 零卡牌可达关卡比 < 1.3 | C34: 卡牌效果或数量不足 | D34: 提高 CARD_PWR，或按 06 表建议重做废卡
A35: ★技巧无回报 | B35: 高手 vs 新手可达关卡比 < 1.15 | C35: 超载输出占比不足（OVER_SHARE 过低） | D35: 提高 OVER_SHARE 至 0.70，代价是植物存在感下降
A36: ★固定方向流泛滥 | B36: 玩家连续同方向移动占比 > 40% | C36: ★ 实测：corner 策略在 5×5 比 random 还差 8%，是负技巧 | D36: 新手引导需干预（GDD v0.2 §6-A）：连续 4 次同方向时触发预警提示
A38: 平衡流程（不可跳过）
A39: 阶段 | B39: 活动 | C39: 产出 | D39: 准入条件
A40: 1. 纸面模拟 | B40: ★ 已完成。4 组蒙特卡洛校准（MERGE_RATE / 归一化 / 连锁 / 分层方案） | C40: 校准后的 MERGE_RATE 0.90、AVG_MERGE_COEF 5.47、LOG_CORR 0.78 | D40: ✅ 完成
A41: 2. 数值原型 | B41: 只做棋盘 + 充能 + 附魔伤害的裸 Demo（无战斗） | C41: 验证乐趣假设：精准合成触发超载清屏的瞬间是否成立 | D41: 纸面模拟完成
A42: 3. 可玩原型 | B42: 加入战斗与波次 | C42: 验证压力曲线与注意力分配 | D42: 乐趣假设成立
A43: 4. 小规模测试 | B43: 20–50 人试玩，只观察 Feel 问题，不调数值 | C43: Feel 问题清单 | D43: 核心循环可玩
A44: 5. 数值调优 | B44: 基于埋点做回归分析 | C44: v0.3 数值 | D44: 埋点体系上线
A45: 6. 软启动 A/B | B45: 测三个主旋钮：STEP_REGEN / B_FAIL / HP_BASE | C45: 上线数值配置 | D45: 数值基本稳定
A48: 给开发团队的一句话
A49: V1 垂直切片是生死线。如果 V1（1 主植物 / 3 波 / 2 元素 / 10 张卡）玩起来不爽，加再多内容和养成也救不回来 —— 请在 V1 投入充分的试玩时间，而不是赶着堆内容。

Sheet 10_波次预算表
A1: 关 1 波次预算表 —— 玩家输出能力 vs 敌人 HP（★ v0.2 新增，是 04 表敌人基准数值的来源）
A2: 配平逻辑：先算玩家在该波能打出多少输出，再除以目标余量比，得到敌人总 HP 预算。所有敌人基准 HP 由此反推。
A3: 附魔输出 = 合成次数 × k × log₂(5.47) × 0.78 ÷ 100 × (EP × ELEM_CAP) ｜ 植物输出 = 3 株 × DPS 7 × 时长 × HIT_RATE 0.75
A4: 波 | B4: 时长(秒) | C4: 步数 | D4: 合成次数 | E4: 小附魔次数 | F4: 附魔输出 | G4: 植物输出 | H4: 玩家总输出 | I4: 目标余量比 | J4: 敌人总HP(算) | K4: 实际配置HP | L4: 偏差 | M4: 组成
A5: 1 | B5: 30 | C5: =B5/'01_核心常量'!$D$8+'01_核心常量'!$D$9 | D5: =C5*'01_核心常量'!$D$10 | E5: =D5*'01_核心常量'!$D$20*LOG('01_核心常量'!$D$11,2)*'01_核心常量'!$D$12/'01_核心常量'!$D$19 | F5: =E5*'01_核心常量'!$D$21*'01_核心常量'!$D$22 | G5: ='01_核心常量'!$D$44*'01_核心常量'!$D$46*B5*'01_核心常量'!$D$45 | H5: =F5+G5 | I5: 1.7 | J5: =H5/I5 | K5: 570 | L5: =K5/J5-1 | M5: 6 小兵
A6: 2 | B6: 35 | C6: =B6/'01_核心常量'!$D$8+'01_核心常量'!$D$9 | D6: =C6*'01_核心常量'!$D$10 | E6: =D6*'01_核心常量'!$D$20*LOG('01_核心常量'!$D$11,2)*'01_核心常量'!$D$12/'01_核心常量'!$D$19 | F6: =E6*'01_核心常量'!$D$21*'01_核心常量'!$D$22 | G6: ='01_核心常量'!$D$44*'01_核心常量'!$D$46*B6*'01_核心常量'!$D$45 | H6: =F6+G6 | I6: 1.7 | J6: =H6/I6 | K6: 612 | L6: =K6/J6-1 | M6: 4 小兵 + 4 群聚 + 2 迅捷
A7: 3 | B7: 45 | C7: =B7/'01_核心常量'!$D$8+'01_核心常量'!$D$9 | D7: =C7*'01_核心常量'!$D$10 | E7: =D7*'01_核心常量'!$D$20*LOG('01_核心常量'!$D$11,2)*'01_核心常量'!$D$12/'01_核心常量'!$D$19 | F7: =E7*'01_核心常量'!$D$21*'01_核心常量'!$D$22 | G7: ='01_核心常量'!$D$44*'01_核心常量'!$D$46*B7*'01_核心常量'!$D$45 | H7: =F7+G7 | I7: 1.5 | J7: =H7/I7 | K7: 950 | L7: =K7/J7-1 | M7: 2 重甲 + 6 小兵
A8: 4 | B8: 45 | C8: =B8/'01_核心常量'!$D$8+'01_核心常量'!$D$9 | D8: =C8*'01_核心常量'!$D$10 | E8: =D8*'01_核心常量'!$D$20*LOG('01_核心常量'!$D$11,2)*'01_核心常量'!$D$12/'01_核心常量'!$D$19 | F8: =E8*'01_核心常量'!$D$21*'01_核心常量'!$D$22 | G8: ='01_核心常量'!$D$44*'01_核心常量'!$D$46*B8*'01_核心常量'!$D$45 | H8: =F8+G8 | I8: 1.6 | J8: =H8/I8 | K8: 890 | L8: =K8/J8-1 | M8: 6 迅捷 + 2 重甲
A9: 5 | B9: 60 | C9: =B9/'01_核心常量'!$D$8+'01_核心常量'!$D$9 | D9: =C9*'01_核心常量'!$D$10 | E9: =D9*'01_核心常量'!$D$20*LOG('01_核心常量'!$D$11,2)*'01_核心常量'!$D$12/'01_核心常量'!$D$19 | F9: =E9*'01_核心常量'!$D$21*'01_核心常量'!$D$22 | G9: ='01_核心常量'!$D$44*'01_核心常量'!$D$46*B9*'01_核心常量'!$D$45 | H9: =F9+G9 | I9: 1.44 | J9: =H9/I9 | K9: 1310 | L9: =K9/J9-1 | M9: 1 精英(火盾) + 8 小兵 + 4 群聚
A10: 合计 | H10: =SUM(H5:H9) | J10: =SUM(J5:J9) | K10: =SUM(K5:K9) | L10: =K10/J10-1
A12: 输出占比校验（★ M3 的验收点）
A13: 项目 | B13: 关 1 全关合计 | C13: 占比 | D13: 目标 | E13: 判定
A14: 附魔输出 | B14: =SUM(F5:F9) | C14: =B14/($B$14+$B$15) | D14: 60% | E14: 低于 50% 说明支柱 P2 失守，玩家不滑棋盘也能赢
A15: 植物输出 | B15: =SUM(G5:G9) | C15: =B15/($B$15+$B$16) | D15: 40% | E15: 高于 50% 说明植物抢戏，需再降 PLANT_DPS
A17: ★ 这是 M3 的验收点。v0.1 的实算是 21% : 79%（植物碾压），v0.2 目标 60% : 40%。若实测偏离超过 ±5%，改 EP_BASE 或 PLANT_DPS 而不是改敌人 HP。
A18: 【偏差列用法】|偏差| > 15% 的行会标红，说明「实际配置 HP」与「模型预算 HP」脱节，需要二选一调整。
A19: 【关 1 刻意宽松】整关余量比约 1.6，前 3 关是「我很强」的爽感期。这个爽感期是刻意的 —— 它保证每局前 12 分钟都是正反馈，失败发生在玩家已经投入之后。
