Workbook

Sheet 00_说明
A1: 星序：元素防线 — 调参总表 v0.1
A3: 使用方式
A4: 黄色单元格 | B4: 可调输入参数。改动后全表公式自动重算。
A5: 绿色单元格 | B5: 公式计算结果。请勿手动覆盖，否则断链。
A6: 灰色小字 | B6: 设计理由 / 调参方向说明。
A7: 无底色 | B7: 静态参考数据（文案表、卡池清单等）。
A9: 工作表导航
A10: 01_核心常量 | B10: 全局旋钮。所有其他表的输入源头，优先在这里调。
A11: 02_合成与充能 | B11: 方块值 → 充能 / CV / 各货币 / 附魔伤害的换算表。
A12: 03_波次节奏模型 | B12: 估算每波的步数、合成次数、ΣCV、附魔次数、星核产出。
A13: 04_关卡与敌人 | B13: 1–15 关的敌人强度缩放 vs 玩家战力成长，含「撞墙点」判定。
A14: 05_植物 | B14: 植物基础数值与星级/等级成长公式。
A15: 06_卡牌 | B15: 卡池清单与稀有度权重。
A16: 07_风险决策EV | B16: 继续 / 收工的期望值计算器与保底比例敏感性分析。
A17: 08_养成与花园 | B17: 星尘养成树成本模型与花园产出模型。
A18: 09_验收清单 | B18: 平衡目标与「broken」判定标准 —— playtest 前先读这张。
A20: 所有数值均为 v0.1 假设，未经 playtest 验证。纸面模拟（10,000 局 Monte Carlo）是调参的第一步，不是可选项。
A21: 配套文档：GDD_星序防线_v0.1.md

Sheet 01_核心常量
A1: 核心常量 —— 全局旋钮（黄底可调，改这里会驱动全表）
A3: 分组 | B3: 参数名 | C3: 代号 | D3: 当前值 | E3: 建议范围 | F3: 调参说明
A4: 棋盘 | B4: 棋盘尺寸 | C4: BOARD_N | D4: 5 | E4: 4 / 5 / 6 | F4: 5×5。4×4 在实时压力下死局率过高；6×6 太宽松失去张力。
A5: 棋盘 | B5: 每次移动生成方块数 | C5: SPAWN_N | D5: 1 | E5: 1 – 2 | F5: 保持 1。卡牌「丰饶」可临时 +1。
A6: 棋盘 | B6: 初始方块数 | C6: INIT_N | D6: 2 | E6: 2 – 4 | F6: 留出前期铺垫空间。
A7: 棋盘 | B7: 步数上限 | C7: STEP_MAX | D7: 5 | E7: 3 – 10 | F7: 攒满 5 步可打一套爆发连招，这是「攒劲儿」的爽点来源。
A8: 棋盘 | B8: 步数回复间隔(秒) | C8: STEP_REGEN | D8: 1.5 | E8: 1.0 – 2.5 | F8: ★ 手感主旋钮。直接决定每波步数预算与合成次数。
A9: 棋盘 | B9: 波次开局赠送步数 | C9: STEP_GIFT | D9: 2 | E9: 0 – 4 | F9: 缓解波次切换空窗。
A10: 棋盘 | B10: 每步平均合成次数 | C10: MERGE_RATE | D10: 1.2 | E10: 0.8 – 1.8 | F10: ★ 模型关键假设，必须用 Monte Carlo 校准。新手 0.5，高手 1.8+。
A11: 充能 | B11: 充能条上限 | C11: CHARGE_MAX | D11: 100 | E11: 80 – 150 | F11: ★ 附魔频率主旋钮。目标：每波 3–4 次小附魔。
A12: 充能 | B12: 充能系数 k | C12: CHARGE_K | D12: 4 | E12: 2 – 8 | F12: 充能 = k × (log₂v − 1)。
A13: 附魔 | B13: 基准附魔强度 EP | C13: EP_BASE | D13: 60 | E13: 40 – 100 | F13: 对标第 1 关小兵 HP 40。所有元素效果的乘数基准。
A14: 附魔 | B14: 共鸣第2次加成 | C14: RES2 | D14: 1.4 | E14: 1.2 – 1.6 | F14: 连续同元素第 2 次的威力倍率。
A15: 附魔 | B15: 共鸣第3次+加成 | C15: RES3 | D15: 1.8 | E15: 1.5 – 2.2 | F15: 第 3 次及以后。过低则轮盘编排无意义。
... A31: 关卡 | B31: 关卡间核心回复% | C31: CORE_REGEN | D31: 0.2 | E31: 0 – 0.35 | F31: 鼓励推进。
A32: 成长 | B32: 每关获取卡牌数 | C32: CARD_N | D32: 5 | E32: 3 – 6 | F32: =每关波数。
A33: 成长 | B33: 单卡平均效果 | C33: CARD_PWR | D33: 0.12 | E33: 0.08 – 0.18 | F33: ★ 玩家战力成长主旋钮。
A34: 成长 | B34: 卡牌效率衰减 | C34: CARD_DECAY | D34: 0.88 | E34: 0.80 – 0.95 | F34: 每关卡牌边际收益递减，制造自然撞墙点。
A35: 成长 | B35: 植物基础DPS | C35: PLANT_DPS | D35: 10 | E35: 8 – 14 | F35: 1★1 级单体基准。
A36: 成长 | B36: 初始编队位 | C36: SLOT_BASE | D36: 3 | E36: 2 – 4 | F36: 编队植物数量。
A37: 成长 | B37: 每星DPS加成 | C37: STAR_MULT | D37: 0.2 | E37: 0.15 – 0.30 | F37: 每升 1 星 DPS 提升。5★ = 1.8×。
A38: 成长 | B38: 每级DPS加成 | C38: LV_MULT | D38: 0.02 | E38: 0.015 – 0.03 | F38: 每级 DPS 提升。Lv50 = 1.98×。★ 压缩过大会碾压局内卡牌。
A39: 成长 | B39: 伙伴位效率 | C39: SLOT_EFF | D39: 0.5 | E39: 0.4 – 0.7 | F39: 第 4/5/6 编队位上的伙伴植物按此效率计入战力（伙伴偏辅助向）。
A40: 成长 | B40: 附魔占输出比例 | C40: ENCH_SHARE | D40: 0.45 | E40: 0.3 – 0.6 | F40: ★ 技术水平对总输出的影响权重。见 04 表漏怪模型。
A41: 成长 | B41: 新手合成率 | C41: MR_NOVICE | D41: 0.5 | E41: — | F41: 新手每步平均合成次数（对比 MERGE_RATE 1.2）。
A42: 成长 | B42: 高手合成率 | C42: MR_EXPERT | D42: 1.8 | E42: — | F42: 高手每步平均合成次数。
A43: 风险 | B43: 失败保底比例 | C43: B_FAIL | D43: 0.4 | E43: 0.2 – 0.6 | F43: ★★ 冒险倾向主旋钮。0.4 → 继续阈值 p>43%。见 07 表。
A44: 风险 | B44: 下一关收益/当前池 | C44: R_RATIO | D44: 0.8 | E44: 0.5 – 1.2 | F44: 由关卡收益倍率递增推导。
... A47: 养成 | B47: 养成树最大等级 | C47: TREE_MAX | D47: 10 | E47: 8 – 15 | F47: 每分支等级上限。

Sheet 02_合成与充能
A1: 方块值 → 充能 / 结晶 / 各货币 / 附魔伤害 换算表
A3: 方块值 v | B3: log₂v | C3: 充能值 | D3: 是否超载 | E3: 品质 | F3: 威力系数 | G3: 附魔伤害(0★EP) | H3: CV(合成) | I3: CV(升华) | J3: 星核 | K3: 核心 | L3: 金币(关1) | M3: 碎片(关1)
A4: 4 | B4: 2 | C4: ='01_核心常量'!$D$12*(B4-1) | D4: — | E4: — | F4: — | G4: — | H4: =A4 | I4: =IF(A4>='01_核心常量'!$D$20,A4*'01_核心常量'!$D$19,0) | J4: =H4*'01_核心常量'!$D$16 | K4: 0 | L4: =H4*'01_核心常量'!$D$17 | M4: =H4*'01_核心常量'!$D$18
A5: 8 | B5: 3 | C5: ='01_核心常量'!$D$12*(B5-1) | D5: — | E5: — | F5: — | G5: — | H5: =A5 | I5: =IF(A5>='01_核心常量'!$D$20,A5*'01_核心常量'!$D$19,0) | J5: =H5*'01_核心常量'!$D$16 | K5: 0 | L5: =H5*'01_核心常量'!$D$17 | M5: =H5*'01_核心常量'!$D$18
A6: 16 | B6: 4 | C6: ='01_核心常量'!$D$12*(B6-1) | D6: — | E6: — | F6: — | G6: — | H6: =A6 | I6: =IF(A6>='01_核心常量'!$D$20,A6*'01_核心常量'!$D$19,0) | J6: =H6*'01_核心常量'!$D$16 | K6: 0 | L6: =H6*'01_核心常量'!$D$17 | M6: =H6*'01_核心常量'!$D$18
A7: 32 | B7: 5 | C7: ='01_核心常量'!$D$12*(B7-1) | D7: — | E7: — | F7: — | G7: — | H7: =A7 | I7: =IF(A7>='01_核心常量'!$D$20,A7*'01_核心常量'!$D$19,0) | J7: =H7*'01_核心常量'!$D$16 | K7: 0 | L7: =H7*'01_核心常量'!$D$17 | M7: =H7*'01_核心常量'!$D$18
A8: 64 | B8: 6 | C8: ='01_核心常量'!$D$12*(B8-1) | D8: — | E8: — | F8: — | G8: — | H8: =A8 | I8: =IF(A8>='01_核心常量'!$D$20,A8*'01_核心常量'!$D$19,0) | J8: =H8*'01_核心常量'!$D$16 | K8: 0 | L8: =H8*'01_核心常量'!$D$17 | M8: =H8*'01_核心常量'!$D$18
A9: 128 | B9: 7 | C9: ='01_核心常量'!$D$12*(B9-1) | D9: — | E9: — | F9: — | G9: — | H9: =A9 | I9: =IF(A9>='01_核心常量'!$D$20,A9*'01_核心常量'!$D$19,0) | J9: =H9*'01_核心常量'!$D$16 | K9: 1 | L9: =H9*'01_核心常量'!$D$17 | M9: =H9*'01_核心常量'!$D$18
A10: 256 | B10: 8 | C10: ='01_核心常量'!$D$12*(B10-1) | D10: 超载 | E10: 1★ | F10: 2 | G10: ='01_核心常量'!$D$13*F10 | H10: =A10 | I10: =IF(A10>='01_核心常量'!$D$20,A10*'01_核心常量'!$D$19,0) | J10: =H10*'01_核心常量'!$D$16 | K10: 1 | L10: =H10*'01_核心常量'!$D$17 | M10: =H10*'01_核心常量'!$D$18
A11: 512 | B11: 9 | C11: ='01_核心常量'!$D$12*(B11-1) | D11: 超载 | E11: 2★ | F11: 3.5 | G11: ='01_核心常量'!$D$13*F11 | H11: =A11 | I11: =IF(A11>='01_核心常量'!$D$20,A11*'01_核心常量'!$D$19,0) | J11: =H11*'01_核心常量'!$D$16 | K11: 3 | L11: =H11*'01_核心常量'!$D$17 | M11: =H11*'01_核心常量'!$D$18
A12: 1024 | B12: 10 | C12: ='01_核心常量'!$D$12*(B12-1) | D12: 超载 | E12: 3★ | F12: 6 | G12: ='01_核心常量'!$D$13*F12 | H12: =A12 | I12: =IF(A12>='01_核心常量'!$D$20,A12*'01_核心常量'!$D$19,0) | J12: =H12*'01_核心常量'!$D$16 | K12: 3 | L12: =H12*'01_核心常量'!$D$17 | M12: =H12*'01_核心常量'!$D$18
A13: 2048 | B13: 11 | C13: ='01_核心常量'!$D$12*(B13-1) | D13: 超载 | E13: 4★ | F13: 10 | G13: ='01_核心常量'!$D$13*F13 | H13: =A13 | I13: =IF(A13>='01_核心常量'!$D$20,A13*'01_核心常量'!$D$19,0) | J13: =H13*'01_核心常量'!$D$16 | K13: 8 | L13: =H13*'01_核心常量'!$D$17 | M13: =H13*'01_核心常量'!$D$18
A14: 4096 | B14: 12 | C14: ='01_核心常量'!$D$12*(B14-1) | D14: 超载 | E14: 5★ | F14: 16 | G14: ='01_核心常量'!$D$13*F14 | H14: =A14 | I14: =IF(A14>='01_核心常量'!$D$20,A14*'01_核心常量'!$D$19,0) | J14: =H14*'01_核心常量'!$D$16 | K14: 8 | L14: =H14*'01_核心常量'!$D$17 | M14: =H14*'01_核心常量'!$D$18
A15: 8192 | B15: 13 | C15: ='01_核心常量'!$D$12*(B15-1) | D15: — | E15: — | F15: — | G15: — | H15: =A15 | I15: =IF(A15>='01_核心常量'!$D$20,A15*'01_核心常量'!$D$19,0) | J15: =H15*'01_核心常量'!$D$16 | K15: 8 | L15: =H15*'01_核心常量'!$D$17 | M15: =H15*'01_核心常量'!$D$18
A17: 共鸣倍率（连续同元素触发）
A18: 连续次数 | B18: 威力加成 | C18: 等效附魔伤害 | D18: 说明
A19: 1 | B19: 1 | C19: ='01_核心常量'!$D$13*B19 | D19: 首次触发，基准。
A20: 2 | B20: ='01_核心常量'!$D$14 | C20: ='01_核心常量'!$D$13*B20 | D20: 轮盘排 [X,X] 的收益。
A21: 3+ | B21: ='01_核心常量'!$D$15 | C21: ='01_核心常量'!$D$13*B21 | D21: 附带「元素余韵」：持续类效果时长 +50%。轮盘排 [X,X,X] 是爆发构筑核心。
A23: 设计校验：一次 2048 超载 = 4★ × EP = 600 伤害 = 15 个第 1 关小兵。这是玩家截图分享的 jackpot 时刻。
A24: 设计校验：最低合成（4）只给 4 充能，最高（2048）给 40。差距 10 倍 —— 保证大数字的战略价值，同时小合成不至于毫无意义。
A25: 调参方向：若埋点显示每波小附魔 > 6 次，升高 CHARGE_MAX 或降低 CHARGE_K；若 < 2 次则反向。

Sheet 03_波次节奏模型
A1: 波次节奏模型 —— 估算每波产出（★ MERGE_RATE 与平均合成值必须用 Monte Carlo 校准）
A3: 关卡 | B3: 生成池 | C3: 生成期望 | D3: 平均合成值 | E3: 每波步数 | F3: 合成次数/波 | G3: ΣCV/波 | H3: 充能/波 | I3: 小附魔/波 | J3: 星核/波 | K3: 金币/波 | L3: 碎片/波 | M3: 目标校验
A4: 1 | B4: 2(90%)/4(10%) | C4: 2.2 | D4: 7 | E4: ='01_核心常量'!$D$21/'01_核心常量'!$D$8+'01_核心常量'!$D$9 | F4: =E4*'01_核心常量'!$D$10 | G4: =F4*D4 | H4: =F4*'01_核心常量'!$D$12*(LOG(D4,2)-1) | I4: =H4/'01_核心常量'!$D$11 | J4: =G4*'01_核心常量'!$D$16 | K4: =G4*'01_核心常量'!$D$17*(1+'01_核心常量'!$D$29*(A4-1)) | L4: =G4*'01_核心常量'!$D$18*(1+'01_核心常量'!$D$29*(A4-1)) | M4: ★目标 3–4 次/波
A5: 2 | B5: 2(90%)/4(10%) | C5: 2.2 | D5: 8 | E5: ='01_核心常量'!$D$21/'01_核心常量'!$D$8+'01_核心常量'!$D$9 | F5: =E5*'01_核心常量'!$D$10 | G5: =F5*D5 | H5: =F5*'01_核心常量'!$D$12*(LOG(D5,2)-1) | I5: =H5/'01_核心常量'!$D$11 | J5: =G5*'01_核心常量'!$D$16 | K5: =G5*'01_核心常量'!$D$17*(1+'01_核心常量'!$D$29*(A5-1)) | L5: =G5*'01_核心常量'!$D$18*(1+'01_核心常量'!$D$29*(A5-1)) | M5: ★目标 3–4 次/波
A6: 3 | B6: 4(80%)/8(20%) | C6: 4.8 | D6: 16 | E6: ='01_核心常量'!$D$21/'01_核心常量'!$D$8+'01_核心常量'!$D$9 | F6: =E6*'01_核心常量'!$D$10 | G6: =F6*D6 | H6: =F6*'01_核心常量'!$D$12*(LOG(D6,2)-1) | I6: =H6/'01_核心常量'!$D$11 | J6: =G6*'01_核心常量'!$D$16 | K6: =G6*'01_核心常量'!$D$17*(1+'01_核心常量'!$D$29*(A6-1)) | L6: =G6*'01_核心常量'!$D$18*(1+'01_核心常量'!$D$29*(A6-1))
A7: 4 | B7: 4(80%)/8(20%) | C7: 4.8 | D7: 18 | E7: ='01_核心常量'!$D$21/'01_核心常量'!$D$8+'01_核心常量'!$D$9 | F7: =E7*'01_核心常量'!$D$10 | G7: =F7*D7 | H7: =F7*'01_核心常量'!$D$12*(LOG(D7,2)-1) | I7: =H7/'01_核心常量'!$D$11 | J7: =G7*'01_核心常量'!$D$16 | K7: =G7*'01_核心常量'!$D$17*(1+'01_核心常量'!$D$29*(A7-1)) | L7: =G7*'01_核心常量'!$D$18*(1+'01_核心常量'!$D$29*(A7-1))
A8: 5 | B8: 8(80%)/16(20%) | C8: 9.6 | D8: 34 | E8: ='01_核心常量'!$D$21/'01_核心常量'!$D$8+'01_核心常量'!$D$9 | F8: =E8*'01_核心常量'!$D$10 | G8: =F8*D8 | H8: =F8*'01_核心常量'!$D$12*(LOG(D8,2)-1) | I8: =H8/'01_核心常量'!$D$11 | J8: =G8*'01_核心常量'!$D$16 | K8: =G8*'01_核心常量'!$D$17*(1+'01_核心常量'!$D$29*(A8-1)) | L8: =G8*'01_核心常量'!$D$18*(1+'01_核心常量'!$D$29*(A8-1))
A9: 6 | B9: 8(80%)/16(20%) | C9: 9.6 | D9: 38 | E9: ='01_核心常量'!$D$21/'01_核心常量'!$D$8+'01_核心常量'!$D$9 | F9: =E9*'01_核心常量'!$D$10 | G9: =F9*D9 | H9: =F9*'01_核心常量'!$D$12*(LOG(D9,2)-1) | I9: =H9/'01_核心常量'!$D$11 | J9: =G9*'01_核心常量'!$D$16 | K9: =G9*'01_核心常量'!$D$17*(1+'01_核心常量'!$D$29*(A9-1)) | L9: =G9*'01_核心常量'!$D$18*(1+'01_核心常量'!$D$29*(A9-1))
A10: 7 | B10: 16(85%)/32(15%) | C10: 18.4 | D10: 64 | E10: ='01_核心常量'!$D$21/'01_核心常量'!$D$8+'01_核心常量'!$D$9 | F10: =E10*'01_核心常量'!$D$10 | G10: =F10*D10 | H10: =F10*'01_核心常量'!$D$12*(LOG(D10,2)-1) | I10: =H10/'01_核心常量'!$D$11 | J10: =G10*'01_核心常量'!$D$16 | K10: =G10*'01_核心常量'!$D$17*(1+'01_核心常量'!$D$29*(A10-1)) | L10: =G10*'01_核心常量'!$D$18*(1+'01_核心常量'!$D$29*(A10-1)) | M10: 偏高，需校准
A11: 8 | B11: 16(85%)/32(15%) | C11: 18.4 | D11: 70 | E11: ='01_核心常量'!$D$21/'01_核心常量'!$D$8+'01_核心常量'!$D$9 | F11: =E11*'01_核心常量'!$D$10 | G11: =F11*D11 | H11: =F11*'01_核心常量'!$D$12*(LOG(D11,2)-1) | I11: =H11/'01_核心常量'!$D$11 | J11: =G11*'01_核心常量'!$D$16 | K11: =G11*'01_核心常量'!$D$17*(1+'01_核心常量'!$D$29*(A11-1)) | L11: =G11*'01_核心常量'!$D$18*(1+'01_核心常量'!$D$29*(A11-1)) | M11: 偏高，需校准
A12: 9 | B12: 32(85%)/64(15%) | C12: 36.8 | D12: 130 | E12: ='01_核心常量'!$D$21/'01_核心常量'!$D$8+'01_核心常量'!$D$9 | F12: =E12*'01_核心常量'!$D$10 | G12: =F12*D12 | H12: =F12*'01_核心常量'!$D$12*(LOG(D12,2)-1) | I12: =H12/'01_核心常量'!$D$11 | J12: =G12*'01_核心常量'!$D$16 | K12: =G12*'01_核心常量'!$D$17*(1+'01_核心常量'!$D$29*(A12-1)) | L12: =G12*'01_核心常量'!$D$18*(1+'01_核心常量'!$D$29*(A12-1)) | M12: 偏高，需校准
A13: 10 | B13: 32(85%)/64(15%) | C13: 36.8 | D13: 140 | E13: ='01_核心常量'!$D$21/'01_核心常量'!$D$8+'01_核心常量'!$D$9 | F13: =E13*'01_核心常量'!$D$10 | G13: =F13*D13 | H13: =F13*'01_核心常量'!$D$12*(LOG(D13,2)-1) | I13: =H13/'01_核心常量'!$D$11 | J13: =G13*'01_核心常量'!$D$16 | K13: =G13*'01_核心常量'!$D$17*(1+'01_核心常量'!$D$29*(A13-1)) | L13: =G13*'01_核心常量'!$D$18*(1+'01_核心常量'!$D$29*(A13-1)) | M13: 偏高，需校准
A14: 12 | B14: 32(85%)/64(15%) | C14: 36.8 | D14: 155 | E14: ='01_核心常量'!$D$21/'01_核心常量'!$D$8+'01_核心常量'!$D$9 | F14: =E14*'01_核心常量'!$D$10 | G14: =F14*D14 | H14: =F14*'01_核心常量'!$D$12*(LOG(D14,2)-1) | I14: =H14/'01_核心常量'!$D$11 | J14: =G14*'01_核心常量'!$D$16 | K14: =G14*'01_核心常量'!$D$17*(1+'01_核心常量'!$D$29*(A14-1)) | L14: =G14*'01_核心常量'!$D$18*(1+'01_核心常量'!$D$29*(A14-1)) | M14: 偏高，需校准
A15: 15 | B15: 32(85%)/64(15%) | C15: 36.8 | D15: 170 | E15: ='01_核心常量'!$D$21/'01_核心常量'!$D$8+'01_核心常量'!$D$9 | F15: =E15*'01_核心常量'!$D$10 | G15: =F15*D15 | H15: =F15*'01_核心常量'!$D$12*(LOG(D15,2)-1) | I15: =H15/'01_核心常量'!$D$11 | J15: =G15*'01_核心常量'!$D$16 | K15: =G15*'01_核心常量'!$D$17*(1+'01_核心常量'!$D$29*(A15-1)) | L15: =G15*'01_核心常量'!$D$18*(1+'01_核心常量'!$D$29*(A15-1)) | M15: 偏高，需校准
A17: 【模型警告】「平均合成值」列是估算值，标记黄色。真实值必须用 10,000 局 Monte Carlo 统计得出，这是纸面原型阶段的首要任务。
A18: 【设计意图】星核/波 目标 20–30，即每波可释放约 1 次战术指令。若超过 50，说明玩家能靠指令无限续命，战斗压力失效。
A19: 【设计意图】小附魔/波 随关卡上升是刻意的 —— 后期玩家应该感到「元素轰炸」，这是爽感成长曲线的一部分，但也必须监控不超 6 次。

Sheet 04_关卡与敌人
A1: 关卡缩放 —— 敌人强度 vs 玩家战力成长（含自然撞墙点判定）
A3: 关卡 n | B3: 敌人HP倍率 | C3: 敌人伤害倍率 | D3: 敌人速度倍率 | E3: 关卡收益倍率 | F3: 玩家战力倍率 | G3: 余量比 | H3: 状态 | I3: 第5波敌人总HP(估) | J3: 玩家DPS(估)
A4: 1 | B4: ='01_核心常量'!$D$23^(A4-1)*(1+'01_核心常量'!$D$24*(A4-1)) | C4: ='01_核心常量'!$D$28^(A4-1) | D4: =1+'01_核心常量'!$D$27*(A4-1) | E4: 1 | F4: 1 | G4: =F4/B4 | H4: =IF(G4>1.15,"轻松",IF(G4>0.85,"势均力敌",IF(G4>0.6,"吃力","撞墙"))) | I4: =1400*B4 | J4: ='01_核心常量'!$D$35*'01_核心常量'!$D$36*F4
A5: 2 | B5: ='01_核心常量'!$D$23^(A5-1)*(1+'01_核心常量'!$D$24*(A5-1)) | C5: ='01_核心常量'!$D$28^(A5-1) | D5: =1+'01_核心常量'!$D$27*(A5-1) | E5: =E4+'01_核心常量'!$D$29+0.1*(A5-2) | F5: =F4*(1+'01_核心常量'!$D$33*'01_核心常量'!$D$34^(A5-2))^'01_核心常量'!$D$32 | G5: =F5/B5 | H5: =IF(G5>1.15,"轻松",IF(G5>0.85,"势均力敌",IF(G5>0.6,"吃力","撞墙"))) | I5: =1400*B5 | J5: ='01_核心常量'!$D$35*'01_核心常量'!$D$36*F5
A6: 3 | B6: ='01_核心常量'!$D$23^(A6-1)*(1+'01_核心常量'!$D$24*(A6-1)) | C6: ='01_核心常量'!$D$28^(A6-1) | D6: =1+'01_核心常量'!$D$27*(A6-1) | E6: =E5+'01_核心常量'!$D$29+0.1*(A6-2) | F6: =F5*(1+'01_核心常量'!$D$33*'01_核心常量'!$D$34^(A6-2))^'01_核心常量'!$D$32 | G6: =F6/B6 | H6: =IF(G6>1.15,"轻松",IF(G6>0.85,"势均力敌",IF(G6>0.6,"吃力","撞墙"))) | I6: =1400*B6 | J6: ='01_核心常量'!$D$35*'01_核心常量'!$D$36*F6
A7: 4 | B7: ='01_核心常量'!$D$23^(A7-1)*(1+'01_核心常量'!$D$24*(A7-1)) | C7: ='01_核心常量'!$D$28^(A7-1) | D7: =1+'01_核心常量'!$D$27*(A7-1) | E7: =E6+'01_核心常量'!$D$29+0.1*(A7-2) | F7: =F6*(1+'01_核心常量'!$D$33*'01_核心常量'!$D$34^(A7-2))^'01_核心常量'!$D$32 | G7: =F7/B7 | H7: =IF(G7>1.15,"轻松",IF(G7>0.85,"势均力敌",IF(G7>0.6,"吃力","撞墙"))) | I7: =1400*B7 | J7: ='01_核心常量'!$D$35*'01_核心常量'!$D$36*F7
A8: 5 | B8: ='01_核心常量'!$D$23^(A8-1)*(1+'01_核心常量'!$D$24*(A8-1)) | C8: ='01_核心常量'!$D$28^(A8-1) | D8: =1+'01_核心常量'!$D$27*(A8-1) | E8: =E7+'01_核心常量'!$D$29+0.1*(A8-2) | F8: =F7*(1+'01_核心常量'!$D$33*'01_核心常量'!$D$34^(A8-2))^'01_核心常量'!$D$32 | G8: =F8/B8 | H8: =IF(G8>1.15,"轻松",IF(G8>0.85,"势均力敌",IF(G8>0.6,"吃力","撞墙"))) | I8: =1400*B8 | J8: ='01_核心常量'!$D$35*'01_核心常量'!$D$36*F8
A9: 6 | B9: ='01_核心常量'!$D$23^(A9-1)*(1+'01_核心常量'!$D$24*(A9-1)) | C9: ='01_核心常量'!$D$28^(A9-1) | D9: =1+'01_核心常量'!$D$27*(A9-1) | E9: =E8+'01_核心常量'!$D$29+0.1*(A9-2) | F9: =F8*(1+'01_核心常量'!$D$33*'01_核心常量'!$D$34^(A9-2))^'01_核心常量'!$D$32 | G9: =F9/B9 | H9: =IF(G9>1.15,"轻松",IF(G9>0.85,"势均力敌",IF(G9>0.6,"吃力","撞墙"))) | I9: =1400*B9 | J9: ='01_核心常量'!$D$35*'01_核心常量'!$D$36*F9
A10: 7 | B10: ='01_核心常量'!$D$23^(A10-1)*(1+'01_核心常量'!$D$24*(A10-1)) | C10: ='01_核心常量'!$D$28^(A10-1) | D10: =1+'01_核心常量'!$D$27*(A10-1) | E10: =E9+'01_核心常量'!$D$29+0.1*(A10-2) | F10: =F9*(1+'01_核心常量'!$D$33*'01_核心常量'!$D$34^(A10-2))^'01_核心常量'!$D$32 | G10: =F10/B10 | H10: =IF(G10>1.15,"轻松",IF(G10>0.85,"势均力敌",IF(G10>0.6,"吃力","撞墙"))) | I10: =1400*B10 | J10: ='01_核心常量'!$D$35*'01_核心常量'!$D$36*F10
A11: 8 | B11: ='01_核心常量'!$D$23^(A11-1)*(1+'01_核心常量'!$D$24*(A11-1)) | C11: ='01_核心常量'!$D$28^(A11-1) | D11: =1+'01_核心常量'!$D$27*(A11-1) | E11: =E10+'01_核心常量'!$D$29+0.1*(A11-2) | F11: =F10*(1+'01_核心常量'!$D$33*'01_核心常量'!$D$34^(A11-2))^'01_核心常量'!$D$32 | G11: =F11/B11 | H11: =IF(G11>1.15,"轻松",IF(G11>0.85,"势均力敌",IF(G11>0.6,"吃力","撞墙"))) | I11: =1400*B11 | J11: ='01_核心常量'!$D$35*'01_核心常量'!$D$36*F11
A12: 9 | B12: ='01_核心常量'!$D$23^(A12-1)*(1+'01_核心常量'!$D$24*(A12-1)) | C12: ='01_核心常量'!$D$28^(A12-1) | D12: =1+'01_核心常量'!$D$27*(A12-1) | E12: =E11+'01_核心常量'!$D$29+0.1*(A12-2) | F12: =F11*(1+'01_核心常量'!$D$33*'01_核心常量'!$D$34^(A12-2))^'01_核心常量'!$D$32 | G12: =F12/B12 | H12: =IF(G12>1.15,"轻松",IF(G12>0.85,"势均力敌",IF(G12>0.6,"吃力","撞墙"))) | I12: =1400*B12 | J12: ='01_核心常量'!$D$35*'01_核心常量'!$D$36*F12
A13: 10 | B13: ='01_核心常量'!$D$23^(A13-1)*(1+'01_核心常量'!$D$24*(A13-1)) | C13: ='01_核心常量'!$D$28^(A13-1) | D13: =1+'01_核心常量'!$D$27*(A13-1) | E13: =E12+'01_核心常量'!$D$29+0.1*(A13-2) | F13: =F12*(1+'01_核心常量'!$D$33*'01_核心常量'!$D$34^(A13-2))^'01_核心常量'!$D$32 | G13: =F13/B13 | H13: =IF(G13>1.15,"轻松",IF(G13>0.85,"势均力敌",IF(G13>0.6,"吃力","撞墙"))) | I13: =1400*B13 | J13: ='01_核心常量'!$D$35*'01_核心常量'!$D$36*F13
A14: 11 | B14: ='01_核心常量'!$D$23^(A14-1)*(1+'01_核心常量'!$D$24*(A14-1)) | C14: ='01_核心常量'!$D$28^(A14-1) | D14: =1+'01_核心常量'!$D$27*(A14-1) | E14: =E13+'01_核心常量'!$D$29+0.1*(A14-2) | F14: =F13*(1+'01_核心常量'!$D$33*'01_核心常量'!$D$34^(A14-2))^'01_核心常量'!$D$32 | G14: =F14/B14 | H14: =IF(G14>1.15,"轻松",IF(G14>0.85,"势均力敌",IF(G14>0.6,"吃力","撞墙"))) | I14: =1400*B14 | J14: ='01_核心常量'!$D$35*'01_核心常量'!$D$36*F14
A15: 12 | B15: ='01_核心常量'!$D$23^(A15-1)*(1+'01_核心常量'!$D$24*(A15-1)) | C15: ='01_核心常量'!$D$28^(A15-1) | D15: =1+'01_核心常量'!$D$27*(A15-1) | E15: =E14+'01_核心常量'!$D$29+0.1*(A15-2) | F15: =F14*(1+'01_核心常量'!$D$33*'01_核心常量'!$D$34^(A15-2))^'01_核心常量'!$D$32 | G15: =F15/B15 | H15: =IF(G15>1.15,"轻松",IF(G15>0.85,"势均力敌",IF(G15>0.6,"吃力","撞墙"))) | I15: =1400*B15 | J15: ='01_核心常量'!$D$35*'01_核心常量'!$D$36*F15
A16: 13 | B16: ='01_核心常量'!$D$23^(A16-1)*(1+'01_核心常量'!$D$24*(A16-1)) | C16: ='01_核心常量'!$D$28^(A16-1) | D16: =1+'01_核心常量'!$D$27*(A16-1) | E16: =E15+'01_核心常量'!$D$29+0.1*(A16-2) | F16: =F15*(1+'01_核心常量'!$D$33*'01_核心常量'!$D$34^(A16-2))^'01_核心常量'!$D$32 | G16: =F16/B16 | H16: =IF(G16>1.15,"轻松",IF(G16>0.85,"势均力敌",IF(G16>0.6,"吃力","撞墙"))) | I16: =1400*B16 | J16: ='01_核心常量'!$D$35*'01_核心常量'!$D$36*F16
... A18: 15 | B18: ='01_核心常量'!$D$23^(A18-1)*(1+'01_核心常量'!$D$24*(A18-1)) | C18: ='01_核心常量'!$D$28^(A18-1) | D18: =1+'01_核心常量'!$D$27*(A18-1) | E18: =E17+'01_核心常量'!$D$29+0.1*(A18-2) | F18: =F17*(1+'01_核心常量'!$D$33*'01_核心常量'!$D$34^(A18-2))^'01_核心常量'!$D$32 | G18: =F18/B18 | H18: =IF(G18>1.15,"轻松",IF(G18>0.85,"势均力敌",IF(G18>0.6,"吃力","撞墙"))) | I18: =1400*B18 | J18: ='01_核心常量'!$D$35*'01_核心常量'!$D$36*F18
A20: 【余量比判读】>1.15 轻松 / 0.85–1.15 势均力敌 / 0.6–0.85 吃力 / <0.6 撞墙。
A21: ★【重要】余量比只是 DPS 上限，是乐观估计。玩家真正的死因不是「打不动」，而是「漏过去的敌人把核心打爆」。必须用下面的漏怪模型判定实际死亡关卡。
A23: 漏怪预算模型 —— 真实死亡关卡判定
A24: 逻辑：当 DPS 余量比 < 1 时，缺口比例的敌人会漏过防线；漏怪数 × 敌人伤害 > 核心 HP 即阵亡。
A25: 关卡 n | B25: 余量比(基准) | C25: 可承受漏怪数 | D25: 新手(合成率0.5) | E25: 中等(1.2) | F25: 高手(1.8) | G25: 满养成高手
A26: 1 | B26: =F4 | C26: ='01_核心常量'!$D$30/('01_核心常量'!$D$26*'01_核心常量'!$D$28^(A26-1)) | D26: =IF('01_核心常量'!$D$25*MAX(0,1-B26*(1-'01_核心常量'!$D$40+'01_核心常量'!$D$40*'01_核心常量'!$D$41/'01_核心常量'!$D$10)*1)<C26,"存活","阵亡") | E26: =IF('01_核心常量'!$D$25*MAX(0,1-B26*1*1)<C26,"存活","阵亡") | F26: =IF('01_核心常量'!$D$25*MAX(0,1-B26*(1-'01_核心常量'!$D$40+'01_核心常量'!$D$40*'01_核心常量'!$D$42/'01_核心常量'!$D$10)*1)<C26,"存活","阵亡") | G26: =IF('01_核心常量'!$D$25*MAX(0,1-B26*(1-'01_核心常量'!$D$40+'01_核心常量'!$D$40*'01_核心常量'!$D$42/'01_核心常量'!$D$10)*1.6)<C26,"存活","阵亡")
A27: 2 | B27: =F5 | C27: ='01_核心常量'!$D$30/('01_核心常量'!$D$26*'01_核心常量'!$D$28^(A27-1)) | D27: =IF('01_核心常量'!$D$25*MAX(0,1-B27*(1-'01_核心常量'!$D$40+'01_核心常量'!$D$40*'01_核心常量'!$D$41/'01_核心常量'!$D$10)*1)<C27,"存活","阵亡") | E27: =IF('01_核心常量'!$D$25*MAX(0,1-B27*1*1)<C27,"存活","阵亡") | F27: =IF('01_核心常量'!$D$25*MAX(0,1-B27*(1-'01_核心常量'!$D$40+'01_核心常量'!$D$40*'01_核心常量'!$D$42/'01_核心常量'!$D$10)*1)<C27,"存活","阵亡") | G27: =IF('01_核心常量'!$D$25*MAX(0,1-B27*(1-'01_核心常量'!$D$40+'01_核心常量'!$D$40*'01_核心常量'!$D$42/'01_核心常量'!$D$10)*1.6)<C27,"存活","阵亡")
A28: 3 | B28: =F6 | C28: ='01_核心常量'!$D$30/('01_核心常量'!$D$26*'01_核心常量'!$D$28^(A28-1)) | D28: =IF('01_核心常量'!$D$25*MAX(0,1-B28*(1-'01_核心常量'!$D$40+'01_核心常量'!$D$40*'01_核心常量'!$D$41/'01_核心常量'!$D$10)*1)<C28,"存活","阵亡") | E28: =IF('01_核心常量'!$D$25*MAX(0,1-B28*1*1)<C28,"存活","阵亡") | F28: =IF('01_核心常量'!$D$25*MAX(0,1-B28*(1-'01_核心常量'!$D$40+'01_核心常量'!$D$40*'01_核心常量'!$D$42/'01_核心常量'!$D$10)*1)<C28,"存活","阵亡") | G28: =IF('01_核心常量'!$D$25*MAX(0,1-B28*(1-'01_核心常量'!$D$40+'01_核心常量'!$D$40*'01_核心常量'!$D$42/'01_核心常量'!$D$10)*1.6)<C28,"存活","阵亡")
A29: 4 | B29: =F7 | C29: ='01_核心常量'!$D$30/('01_核心常量'!$D$26*'01_核心常量'!$D$28^(A29-1)) | D29: =IF('01_核心常量'!$D$25*MAX(0,1-B29*(1-'01_核心常量'!$D$40+'01_核心常量'!$D$40*'01_核心常量'!$D$41/'01_核心常量'!$D$10)*1)<C29,"存活","阵亡") | E29: =IF('01_核心常量'!$D$25*MAX(0,1-B29*1*1)<C29,"存活","阵亡") | F29: =IF('01_核心常量'!$D$25*MAX(0,1-B29*(1-'01_核心常量'!$D$40+'01_核心常量'!$D$40*'01_核心常量'!$D$42/'01_核心常量'!$D$10)*1)<C29,"存活","阵亡") | G29: =IF('01_核心常量'!$D$25*MAX(0,1-B29*(1-'01_核心常量'!$D$40+'01_核心常量'!$D$40*'01_核心常量'!$D$42/'01_核心常量'!$D$10)*1.6)<C29,"存活","阵亡")
A30: 5 | B30: =F8 | C30: ='01_核心常量'!$D$30/('01_核心常量'!$D$26*'01_核心常量'!$D$28^(A30-1)) | D30: =IF('01_核心常量'!$D$25*MAX(0,1-B30*(1-'01_核心常量'!$D$40+'01_核心常量'!$D$40*'01_核心常量'!$D$41/'01_核心常量'!$D$10)*1)<C30,"存活","阵亡") | E30: =IF('01_核心常量'!$D$25*MAX(0,1-B30*1*1)<C30,"存活","阵亡") | F30: =IF('01_核心常量'!$D$25*MAX(0,1-B30*(1-'01_核心常量'!$D$40+'01_核心常量'!$D$40*'01_核心常量'!$D$42/'01_核心常量'!$D$10)*1)<C30,"存活","阵亡") | G30: =IF('01_核心常量'!$D$25*MAX(0,1-B30*(1-'01_核心常量'!$D$40+'01_核心常量'!$D$40*'01_核心常量'!$D$42/'01_核心常量'!$D$10)*1.6)<C30,"存活","阵亡")
A31: 6 | B31: =F9 | C31: ='01_核心常量'!$D$30/('01_核心常量'!$D$26*'01_核心常量'!$D$28^(A31-1)) | D31: =IF('01_核心常量'!$D$25*MAX(0,1-B31*(1-'01_核心常量'!$D$40+'01_核心常量'!$D$40*'01_核心常量'!$D$41/'01_核心常量'!$D$10)*1)<C31,"存活","阵亡") | E31: =IF('01_核心常量'!$D$25*MAX(0,1-B31*1*1)<C31,"存活","阵亡") | F31: =IF('01_核心常量'!$D$25*MAX(0,1-B31*(1-'01_核心常量'!$D$40+'01_核心常量'!$D$40*'01_核心常量'!$D$42/'01_核心常量'!$D$10)*1)<C31,"存活","阵亡") | G31: =IF('01_核心常量'!$D$25*MAX(0,1-B31*(1-'01_核心常量'!$D$40+'01_核心常量'!$D$40*'01_核心常量'!$D$42/'01_核心常量'!$D$10)*1.6)<C31,"存活","阵亡")
A32: 7 | B32: =F10 | C32: ='01_核心常量'!$D$30/('01_核心常量'!$D$26*'01_核心常量'!$D$28^(A32-1)) | D32: =IF('01_核心常量'!$D$25*MAX(0,1-B32*(1-'01_核心常量'!$D$40+'01_核心常量'!$D$40*'01_核心常量'!$D$41/'01_核心常量'!$D$10)*1)<C32,"存活","阵亡") | E32: =IF('01_核心常量'!$D$25*MAX(0,1-B32*1*1)<C32,"存活","阵亡") | F32: =IF('01_核心常量'!$D$25*MAX(0,1-B32*(1-'01_核心常量'!$D$40+'01_核心常量'!$D$40*'01_核心常量'!$D$42/'01_核心常量'!$D$10)*1)<C32,"存活","阵亡") | G32: =IF('01_核心常量'!$D$25*MAX(0,1-B32*(1-'01_核心常量'!$D$40+'01_核心常量'!$D$40*'01_核心常量'!$D$42/'01_核心常量'!$D$10)*1.6)<C32,"存活","阵亡")
A33: 8 | B33: =F11 | C33: ='01_核心常量'!$D$30/('01_核心常量'!$D$26*'01_核心常量'!$D$28^(A33-1)) | D33: =IF('01_核心常量'!$D$25*MAX(0,1-B33*(1-'01_核心常量'!$D$40+'01_核心常量'!$D$40*'01_核心常量'!$D$41/'01_核心常量'!$D$10)*1)<C33,"存活","阵亡") | E33: =IF('01_核心常量'!$D$25*MAX(0,1-B33*1*1)<C33,"存活","阵亡") | F33: =IF('01_核心常量'!$D$25*MAX(0,1-B33*(1-'01_核心常量'!$D$40+'01_核心常量'!$D$40*'01_核心常量'!$D$42/'01_核心常量'!$D$10)*1)<C33,"存活","阵亡") | G33: =IF('01_核心常量'!$D$25*MAX(0,1-B33*(1-'01_核心常量'!$D$40+'01_核心常量'!$D$40*'01_核心常量'!$D$42/'01_核心常量'!$D$10)*1.6)<C33,"存活","阵亡")
A34: 9 | B34: =F12 | C34: ='01_核心常量'!$D$30/('01_核心常量'!$D$26*'01_核心常量'!$D$28^(A34-1)) | D34: =IF('01_核心常量'!$D$25*MAX(0,1-B34*(1-'01_核心常量'!$D$40+'01_核心常量'!$D$40*'01_核心常量'!$D$41/'01_核心常量'!$D$10)*1)<C34,"存活","阵亡") | E34: =IF('01_核心常量'!$D$25*MAX(0,1-B34*1*1)<C34,"存活","阵亡") | F34: =IF('01_核心常量'!$D$25*MAX(0,1-B34*(1-'01_核心常量'!$D$40+'01_核心常量'!$D$40*'01_核心常量'!$D$42/'01_核心常量'!$D$10)*1)<C34,"存活","阵亡") | G34: =IF('01_核心常量'!$D$25*MAX(0,1-B34*(1-'01_核心常量'!$D$40+'01_核心常量'!$D$40*'01_核心常量'!$D$42/'01_核心常量'!$D$10)*1.6)<C34,"存活","阵亡")
A35: 10 | B35: =F13 | C35: ='01_核心常量'!$D$30/('01_核心常量'!$D$26*'01_核心常量'!$D$28^(A35-1)) | D35: =IF('01_核心常量'!$D$25*MAX(0,1-B35*(1-'01_核心常量'!$D$40+'01_核心常量'!$D$40*'01_核心常量'!$D$41/'01_核心常量'!$D$10)*1)<C35,"存活","阵亡") | E35: =IF('01_核心常量'!$D$25*MAX(0,1-B35*1*1)<C35,"存活","阵亡") | F35: =IF('01_核心常量'!$D$25*MAX(0,1-B35*(1-'01_核心常量'!$D$40+'01_核心常量'!$D$40*'01_核心常量'!$D$42/'01_核心常量'!$D$10)*1)<C35,"存活","阵亡") | G35: =IF('01_核心常量'!$D$25*MAX(0,1-B35*(1-'01_核心常量'!$D$40+'01_核心常量'!$D$40*'01_核心常量'!$D$42/'01_核心常量'!$D$10)*1.6)<C35,"存活","阵亡")
A36: 11 | B36: =F14 | C36: ='01_核心常量'!$D$30/('01_核心常量'!$D$26*'01_核心常量'!$D$28^(A36-1)) | D36: =IF('01_核心常量'!$D$25*MAX(0,1-B36*(1-'01_核心常量'!$D$40+'01_核心常量'!$D$40*'01_核心常量'!$D$41/'01_核心常量'!$D$10)*1)<C36,"存活","阵亡") | E36: =IF('01_核心常量'!$D$25*MAX(0,1-B36*1*1)<C36,"存活","阵亡") | F36: =IF('01_核心常量'!$D$25*MAX(0,1-B36*(1-'01_核心常量'!$D$40+'01_核心常量'!$D$40*'01_核心常量'!$D$42/'01_核心常量'!$D$10)*1)<C36,"存活","阵亡") | G36: =IF('01_核心常量'!$D$25*MAX(0,1-B36*(1-'01_核心常量'!$D$40+'01_核心常量'!$D$40*'01_核心常量'!$D$42/'01_核心常量'!$D$10)*1.6)<C36,"存活","阵亡")
A38: 【模型输出（当前配置 HP_BASE=1.55）】新手 3 关 / 中等 6 关 / 高手 7 关 / 满养成高手 9 关。这是设计目标曲线，与「平均到达 4–6 关」的埋点目标自洽。
A39: 【技术水平权重】附魔占输出 45%（ENCH_SHARE）。新手合成率 0.5 → 技术系数 0.74；高手 1.8 → 1.23。这意味着技术差距约 1.65 倍战力，是健康的技巧回报。
A40: 【调参方向】若新手在 3 关就阵亡导致挫败：降低 HP_BASE 至 1.50，或提高第 1–2 关的波次时长给更多缓冲。若中等玩家超过 7 关：升高 HP_BASE 至 1.60。
A42: 敌人基准（第 1 关）
A43: 类型 | B43: HP | C43: 速度(格/秒) | D43: 撞核心伤害 | E43: 护甲 | F43: 掉落材料 | G43: 设计目的
A44: 小兵 Grunt | B44: 40 | C44: 0.35 | D44: 5 | E44: 0 | F44: 0 | G44: 基准单位，定义 DPS 需求底线。
A45: 群聚 Swarm | B45: 12 | C45: 0.5 | D45: 2 | E45: 0 | F45: 0 | G45: 惩罚单体流，奖励火元素与溅射。
A46: 迅捷 Swift | B46: 22 | C46: 0.75 | D46: 3 | E46: 0 | F46: 0 | G46: 惩罚合成太慢，是时间压力的主要载体。
...

Sheet 05_植物
A1: 植物数值与成长模型
A2: 成长公式：DPS = 基础 × (1 + 每星DPS加成×(星级−1)) × (1 + 每级DPS加成×(等级−1)) × 养成树枝叶加成
A3: 植物 | B3: 元素 | C3: 攻击形态 | D3: 基础DPS | E3: 射程(格) | F3: 特性 | G3: 大招(4核心/25s)
A4: 焰心草 | B4: 火 | C4: 直射单体 | D4: 12 | E4: 3 | F4: 命中附加灼烧：3 秒内每秒 3 伤害 | G4: 全场灼烧 8s，每秒 EP×0.15
A5: 潮汐藤 | B5: 水 | C5: 环形 AoE | D5: 7 | E5: 1.5 | F5: 范围内敌人 −20% 移速（持续） | G5: 全体击退 2 格 + 减速 50%（4s）
A6: 荆棘木 | B6: 木 | C6: 穿透直线 | D6: 11 | E6: 无限 | F6: 无视前排阻挡，贯穿本行 | G6: 贯穿全屏光束，EP×3.0
A7: 辉光苔 | B7: 光 | C7: 辅助(无攻击) | D7: 0 | E7: — | F7: 每 10s：+1 步 或 +8 充能（玩家预设） | G7: 立即 +4 步 +60 充能，全植物攻速 +50%（6s）
A8: 雷鸣花 | B8: 雷 | C8: 溅射 | D8: 10 | E8: 2.5 | F8: 命中溅射周围 50% 伤害 | G8: 15 次随机落雷，每次 EP×0.4
A9: 霜晶莲 | B9: 冰 | C9: 直射单体 | D9: 8 | E9: 3 | F9: 命中减速 30%（2s） | G9: 全场冻结 4s，冻结期间受伤 +25%
A11: 星级 / 等级成长曲线（以荆棘木 基础DPS=11 为例）
A12: 等级\星级 | B12: 1★ | C12: 2★ | D12: 3★ | E12: 4★ | F12: 5★
A13: Lv.1 | B13: =11*(1+'01_核心常量'!$D$37*(1-1))*(1+'01_核心常量'!$D$38*(1-1)) | C13: =11*(1+'01_核心常量'!$D$37*(2-1))*(1+'01_核心常量'!$D$38*(1-1)) | D13: =11*(1+'01_核心常量'!$D$37*(3-1))*(1+'01_核心常量'!$D$38*(1-1)) | E13: =11*(1+'01_核心常量'!$D$37*(4-1))*(1+'01_核心常量'!$D$38*(1-1)) | F13: =11*(1+'01_核心常量'!$D$37*(5-1))*(1+'01_核心常量'!$D$38*(1-1))
A14: Lv.10 | B14: =11*(1+'01_核心常量'!$D$37*(1-1))*(1+'01_核心常量'!$D$38*(10-1)) | C14: =11*(1+'01_核心常量'!$D$37*(2-1))*(1+'01_核心常量'!$D$38*(10-1)) | D14: =11*(1+'01_核心常量'!$D$37*(3-1))*(1+'01_核心常量'!$D$38*(10-1)) | E14: =11*(1+'01_核心常量'!$D$37*(4-1))*(1+'01_核心常量'!$D$38*(10-1)) | F14: =11*(1+'01_核心常量'!$D$37*(5-1))*(1+'01_核心常量'!$D$38*(10-1))
A15: Lv.20 | B15: =11*(1+'01_核心常量'!$D$37*(1-1))*(1+'01_核心常量'!$D$38*(20-1)) | C15: =11*(1+'01_核心常量'!$D$37*(2-1))*(1+'01_核心常量'!$D$38*(20-1)) | D15: =11*(1+'01_核心常量'!$D$37*(3-1))*(1+'01_核心常量'!$D$38*(20-1)) | E15: =11*(1+'01_核心常量'!$D$37*(4-1))*(1+'01_核心常量'!$D$38*(20-1)) | F15: =11*(1+'01_核心常量'!$D$37*(5-1))*(1+'01_核心常量'!$D$38*(20-1))
A16: Lv.30 | B16: =11*(1+'01_核心常量'!$D$37*(1-1))*(1+'01_核心常量'!$D$38*(30-1)) | C16: =11*(1+'01_核心常量'!$D$37*(2-1))*(1+'01_核心常量'!$D$38*(30-1)) | D16: =11*(1+'01_核心常量'!$D$37*(3-1))*(1+'01_核心常量'!$D$38*(30-1)) | E16: =11*(1+'01_核心常量'!$D$37*(4-1))*(1+'01_核心常量'!$D$38*(30-1)) | F16: =11*(1+'01_核心常量'!$D$37*(5-1))*(1+'01_核心常量'!$D$38*(30-1))
A17: Lv.40 | B17: =11*(1+'01_核心常量'!$D$37*(1-1))*(1+'01_核心常量'!$D$38*(40-1)) | C17: =11*(1+'01_核心常量'!$D$37*(2-1))*(1+'01_核心常量'!$D$38*(40-1)) | D17: =11*(1+'01_核心常量'!$D$37*(3-1))*(1+'01_核心常量'!$D$38*(40-1)) | E17: =11*(1+'01_核心常量'!$D$37*(4-1))*(1+'01_核心常量'!$D$38*(40-1)) | F17: =11*(1+'01_核心常量'!$D$37*(5-1))*(1+'01_核心常量'!$D$38*(40-1))
A18: Lv.50 | B18: =11*(1+'01_核心常量'!$D$37*(1-1))*(1+'01_核心常量'!$D$38*(50-1)) | C18: =11*(1+'01_核心常量'!$D$37*(2-1))*(1+'01_核心常量'!$D$38*(50-1)) | D18: =11*(1+'01_核心常量'!$D$37*(3-1))*(1+'01_核心常量'!$D$38*(50-1)) | E18: =11*(1+'01_核心常量'!$D$37*(4-1))*(1+'01_核心常量'!$D$38*(50-1)) | F18: =11*(1+'01_核心常量'!$D$37*(5-1))*(1+'01_核心常量'!$D$38*(50-1))
A20: 【设计校验】Lv.50 / 5★ 的荆棘木 = 11 × 1.8 × 1.98 = 39.2 DPS，是初始值的 3.56 倍。配合编队位扩展至 6（伙伴位 50% 效率 → ×1.5），植物侧满养成合计约 5.3 倍。
A21: ★★【平衡红线 · 最重要的一个】养成 vs 局内卡牌的战力占比，建议 60 : 40。
A22: · 若养成占比过高（>75%）：肉鸽三选一沦为过场，局内构筑失去意义，游戏退化成纯数值养成。
A23: · 若养成占比过低（<40%）：H5 产品失去留存与付费主驱动，长期 LTV 崩塌。
A24: · 60:40 的依据：养成是 H5 商业化的主体，但局内卡牌必须保留「每局体验不同」的价值 —— 它的意义在多样性而非数值量级。
A25: · 监控方式：分别统计「满养成 + 零卡牌」与「零养成 + 满卡牌」两种极端配置下的可达关卡，二者之比应落在 1.3 – 1.8 之间。
A27: 六元素效果表（EP = 附魔强度）
A28: 元素 | B28: 定位 | C28: 效果（0★ / EP=60） | D28: 设计意图
A29: 火 | B29: 群体爆发 | C29: 全场敌人立即受到 EP×1.0 伤害；已灼烧目标 +30% | D29: 清群首选，最直观的爽感来源。
A30: 雷 | B30: 单体爆发 | C30: 连锁闪电弹跳 5 次，每次 EP×0.5，优先最前排 | D30: 打 Boss / 重甲。与火形成群-单分工。
A31: 冰 | B31: 控制+增伤 | C31: 全场定身 3s，冻结目标受伤 +25% | D31: 救场技，为爆发铺路。进攻向。
A32: 水 | B32: 持续减速 | C32: 移速 −40%，持续 5s，造成伤害 −20% | D32: 拖时间，给棋盘争取步数。防守向。
A33: 木 | B33: 己方增益 | C33: 植物攻速 +35%，持续 8s；核心回复 EP×0.2 | D33: 长线收益，配合高 DPS 编队才有价值。
A34: 光 | B34: 资源调度 | C34: 清除棋盘所有 ≤4 方块；+2 步；植物伤害 +25%（8s） | D34: 唯一直接强化棋盘的元素，是解卡保底。
A36: 元素护盾（让轮盘编排有外部约束）
A37: 护盾类型 | B37: 效果 | C37: 破解方式 | D37: 设计目的
A38: 元素护盾 · X | B38: 受到非 X 元素伤害 −60% | C38: 用 X 元素附魔 / X 属性植物攻击 | D38: 防止玩家把轮盘排成固定最优解。
A39: 元素易伤 · X | B39: 受到 X 元素伤害 +100% | C39: 针对性编排轮盘 | D39: 奖励开局前的配置决策。

Sheet 06_卡牌
A1: 卡池清单与稀有度权重
A2: 稀有度权重（按关卡）
A3: 关卡 | B3: 普通 | C3: 稀有 | D3: 史诗 | E3: 传说 | F3: 说明
A4: 1 | B4: 0.7 | C4: 0.25 | D4: 0.05 | E4: 0 | F4: 教学期，几乎只有基础卡。
A5: 2 | B5: 0.6 | C5: 0.3 | D5: 0.09 | E5: 0.01 | F5: 首次见到传说，制造惊喜。
A6: 3 | B6: 0.5 | C6: 0.33 | D6: 0.15 | E6: 0.02 | F6: 构筑开始成型。
A7: 4 | B7: 0.42 | C7: 0.35 | D7: 0.18 | E7: 0.05 | F7: 构筑发力期。
A8: 5+ | B8: 0.35 | C8: 0.35 | D8: 0.22 | E8: 0.08 | F8: 后期。同关第 4、5 波再 +5% 稀有度权重。
A10: 卡池
A11: 类别 | B11: 卡名 | C11: 稀有度 | D11: 效果 | E11: 设计备注
A12: 棋盘 | B12: 稳健 | C12: 普通 | D12: 步数上限 +1 | E12: 最基础的节奏卡，前期必拿。
A13: 棋盘 | B13: 疾风 | C13: 普通 | D13: 步数回复速度 +15% | E13: 与稳健形成「容量 vs 速率」选择。
A14: 棋盘 | B14: 聚能 | C14: 普通 | D14: 充能条上限 −10 | E14: 等价于附魔频率 +11%。
A15: 棋盘 | B15: 精准 | C15: 稀有 | D15: 生成值为高档的概率 +25% | E15: 隐性加速，体感不明显但收益高。
A16: 棋盘 | B16: 净化术 | C16: 稀有 | D16: 立即清除所有 ≤8 方块并 +2 步 | E16: 救急卡。
A17: 棋盘 | B17: 丰饶 | C17: 史诗 | D17: 每次移动额外生成 1 个方块 | E17: ★ 双刃卡：产出翻倍，但棋盘更容易满。制造真实抉择。
A18: 棋盘 | B18: 连锁核心 | C18: 传说 | D18: 一次移动中第 3 次及以后的合并，充能与 CV 翻倍 | E18: ★ 奖励布局技巧，是高手与普通玩家的分水岭。
A19: 战斗 | B19: 锋锐 | C19: 普通 | D19: 全植物伤害 +15% | E19: 基准战力卡。
A20: 战斗 | B20: 连射 | C20: 普通 | D20: 全植物攻速 +12% | E20: 与锋锐近似等效，制造选择困难。
A21: 战斗 | B21: 远眺 | C21: 普通 | D21: 全植物射程 +1 | E21: 价值依赖编队，情境性强。
A22: 战斗 | B22: 破甲 | C22: 稀有 | D22: 无视 30% 护甲 | E22: 针对重甲/Boss 波。
... A41: 战术 | B41: 贪婪核心 | C41: 传说 | D41: 关闭自动升华 | E41: ★ 高风险高回报的极限流开关，是升华机制的策略深度所在。
A43: 卡池当前 30 张（含 6 张元素亲和变体则共 35 张）。V2 完整版目标 ≥ 60 张，否则 4–6 关后卡池枯竭，构筑深度崩塌。
A44: 平衡红线：同名卡重复时效果加法叠加而非乘法，防止指数爆炸。若埋点显示某卡选取率 > 70%，说明该卡超模或同类卡过少。
A45: 建议补充机制：卡牌升阶 —— 同名卡可合并强化，缓解后期卡池枯竭（见 GDD 风险 R5）。

Sheet 07_风险决策EV
A1: 继续 / 收工 期望值计算器
A2: 公式：收工 EV = P ｜ 继续 EV = p×(P+R) + (1−p)×b×P ｜ 继续优于收工 ⟺ p > (1−b)P / ((1−b)P + R)
A3: 主计算
A4: 参数 | B4: 值 | C4: 说明
A5: 当前累积收益池 P | B5: 1000 | C5: 任意单位。EV 结论与 P 的绝对值无关，只与 R/P 比例有关。
A6: 下一关预期收益 R | B6: =$B$5*'01_核心常量'!$D$44 | C6: =P × R_RATIO。R_RATIO 由关卡收益倍率递增推导。
A7: 失败保底比例 b | B7: ='01_核心常量'!$D$43 | C7: 引用 01 核心常量 B_FAIL。
A8: 玩家自估通关概率 p | B8: 0.6 | C8: 玩家主观判断。设计目标是让临界阈值足够低，从而鼓励冒险。
A10: 指标 | B10: 值 | C10: 说明
A11: 收工 EV | B11: =$B$5 | C11: 确定性收益。
A12: 继续 EV | B12: =$B$8*($B$5+$B$6)+(1-$B$8)*$B$7*$B$5 | C12: =p×(P+R) + (1−p)×b×P
A13: EV 差值（继续 − 收工） | B13: =$B$12-$B$11 | C13: > 0 表示理性上应该选择继续。
A14: 临界通关概率 p* | B14: =(1-$B$7)*$B$5/((1-$B$7)*$B$5+$B$6) | C14: ★ p > p* 时继续是正期望。这是整个风险系统的核心数字。
A16: 保底比例 b 的敏感性分析（★ 冒险倾向主旋钮）
A17: 保底 b | B17: 临界概率 p* | C17: 玩家行为预测 | D17: 适用产品目标
A18: 0 | B18: =(1-A18)/((1-A18)+'01_核心常量'!$D$44) | C18: 极度保守，玩家会提前收工 | D18: 硬核产品，追求策略纯度
A19: 0.2 | B19: =(1-A19)/((1-A19)+'01_核心常量'!$D$44) | C19: 偏保守，多数玩家 3–4 关收工 | D19: 中核产品，单局时长可控
A20: 0.3 | B20: =(1-A20)/((1-A20)+'01_核心常量'!$D$44) | C20: 略保守 | D20: —
A21: 0.4 | B21: =(1-A21)/((1-A21)+'01_核心常量'!$D$44) | C21: ★ 平衡点，决策有张力 | D21: ★ 推荐：H5 休闲偏中核
A22: 0.5 | B22: =(1-A22)/((1-A22)+'01_核心常量'!$D$44) | C22: 略激进 | D22: —
A23: 0.6 | B23: =(1-A23)/((1-A23)+'01_核心常量'!$D$44) | C23: 激进，玩家几乎不主动收工 | D23: 追求高重开率与广告曝光
A24: 0.8 | B24: =(1-A24)/((1-A24)+'01_核心常量'!$D$44) | C24: 极度激进，收工按钮形同虚设 | D24: 纯广告变现产品
A25: 1 | B25: =(1-A25)/((1-A25)+'01_核心常量'!$D$44) | C25: 无风险，继续永远最优 | D25: 决策消失，不推荐
A27: 【关键洞察】保底比例 b 从 0.2 提到 0.6，临界概率从 50% 降到 33% —— 玩家会明显更爱冒险。这是调节「重开率」最廉价的旋钮，优先用它做 A/B 测。
A28: ★【隐藏的美妙性质】R/P 比例随关卡自然变化：第 2 关约 1.55（p*≈28%，极度鼓励冒险）→ 第 6 关约 0.53（p*≈53%，必须谨慎）。也就是说游戏在早期自动怂恿玩家冒进、后期自动转为审慎 —— 这是收益倍率递增结构带来的免费礼物，不要在调参时破坏它。
A29: 【注意】卡牌「备用核心」（核心归零时以 30% HP 复活一次）等价于把 b 临时抬高，会显著改变玩家在持有该卡时的决策。这张卡的实际价值远高于其描述。
A30: 【UI 强制要求】关卡结算界面必须同屏显示：当前池 / 下一关倍率与威胁等级 / 继续的预估收益 +R / 失败保底规则。缺一项，这个决策就不成立。

Sheet 08_养成与花园
A1: 星尘养成树与花园产出模型
A2: 养成树成本模型
A3: 成本公式：Cost(n) = 基础成本 × 增长系数^(n−1)
A4: 等级 | B4: 单级成本(星尘) | C4: 累计成本 | D4: 根系效果 | E4: 枝叶效果 | F4: 花蕾效果 | G4: 果实效果
A5: 1 | B5: =ROUND('01_核心常量'!$D$45*'01_核心常量'!$D$46^(A5-1),0) | C5: =B5 | D5: 步数+0.2 / 回复+3% / 充能条−2% | E5: 植物伤害+3% / 核心HP+4% | F5: 全元素威力+4% | G5: 金币+4% / 碎片+6% / 花园产出+5%
A6: 2 | B6: =ROUND('01_核心常量'!$D$45*'01_核心常量'!$D$46^(A6-1),0) | C6: =C5+B6 | D6: 步数+0.2 / 回复+3% / 充能条−2% | E6: 植物伤害+3% / 核心HP+4% | F6: 全元素威力+4% | G6: 金币+4% / 碎片+6% / 花园产出+5%
A7: 3 | B7: =ROUND('01_核心常量'!$D$45*'01_核心常量'!$D$46^(A7-1),0) | C7: =C6+B7 | D7: 步数+0.2 / 回复+3% / 充能条−2% | E7: 植物伤害+3% / 核心HP+4% | F7: 全元素威力+4% | G7: 金币+4% / 碎片+6% / 花园产出+5%
A8: 4 | B8: =ROUND('01_核心常量'!$D$45*'01_核心常量'!$D$46^(A8-1),0) | C8: =C7+B8 | D8: 步数+0.2 / 回复+3% / 充能条−2% | E8: 植物伤害+3% / 核心HP+4% | F8: 全元素威力+4% | G8: 金币+4% / 碎片+6% / 花园产出+5%
A9: 5 | B9: =ROUND('01_核心常量'!$D$45*'01_核心常量'!$D$46^(A9-1),0) | C9: =C8+B9 | D9: 步数+0.2 / 回复+3% / 充能条−2% | E9: 植物伤害+3% / 核心HP+4% | F9: 全元素威力+4% | G9: 金币+4% / 碎片+6% / 花园产出+5%
A10: 6 | B10: =ROUND('01_核心常量'!$D$45*'01_核心常量'!$D$46^(A10-1),0) | C10: =C9+B10 | D10: 步数+0.2 / 回复+3% / 充能条−2% | E10: 植物伤害+3% / 核心HP+4% | F10: 全元素威力+4% | G10: 金币+4% / 碎片+6% / 花园产出+5%
A11: 7 | B11: =ROUND('01_核心常量'!$D$45*'01_核心常量'!$D$46^(A11-1),0) | C11: =C10+B11 | D11: 步数+0.2 / 回复+3% / 充能条−2% | E11: 植物伤害+3% / 核心HP+4% | F11: 全元素威力+4% | G11: 金币+4% / 碎片+6% / 花园产出+5%
A12: 8 | B12: =ROUND('01_核心常量'!$D$45*'01_核心常量'!$D$46^(A12-1),0) | C12: =C11+B12 | D12: 步数+0.2 / 回复+3% / 充能条−2% | E12: 植物伤害+3% / 核心HP+4% | F12: 全元素威力+4% | G12: 金币+4% / 碎片+6% / 花园产出+5%
A13: 9 | B13: =ROUND('01_核心常量'!$D$45*'01_核心常量'!$D$46^(A13-1),0) | C13: =C12+B13 | D13: 步数+0.2 / 回复+3% / 充能条−2% | E13: 植物伤害+3% / 核心HP+4% | F13: 全元素威力+4% | G13: 金币+4% / 碎片+6% / 花园产出+5%
A14: 10 | B14: =ROUND('01_核心常量'!$D$45*'01_核心常量'!$D$46^(A14-1),0) | C14: =C13+B14 | D14: 步数+0.2 / 回复+3% / 充能条−2% | E14: 植物伤害+3% / 核心HP+4% | F14: 全元素威力+4% | G14: 金币+4% / 碎片+6% / 花园产出+5%
A15: 满级合计 | C15: =SUM(B5:B14)*4 | D15: 4 分支 × 单分支累计
A17: 【当前配置】基础 40 / 增长 1.30 → 单分支满级约 1,705 星尘，全树约 6,820 星尘。早期花园产出 200–500/天，后期 2,000+/天 → 约 3–5 周长线目标。
A18: 【调参方向】H5 休闲产品建议长线不超过 4 周。若超长，把增长系数降到 1.25（全树约 5,300）；若希望更长线支撑赛季，升到 1.35。
A20: 花园产出模型
A21: 稀有度 | B21: 星尘/小时(基) | C21: 30min | D21: 2h | E21: 6h | F21: 6 盆全传说/6h
A22: 普通 | B22: 8 | C22: =B22*0.5 | D22: =B22*2 | E22: =B22*6 | F22: =B22*6*6
A23: 稀有 | B23: 15 | C23: =B23*0.5 | D23: =B23*2 | E23: =B23*6 | F23: =B23*6*6
A24: 史诗 | B24: 28 | C24: =B24*0.5 | D24: =B24*2 | E24: =B24*6 | F24: =B24*6*6
A25: 传说 | B25: 50 | C25: =B25*0.5 | D25: =B25*2 | E25: =B25*6 | F25: =B25*6*6
A27: 产出速率 = 稀有度基础 × (1 + 星级×0.1) × (1 + 养成树果实分支等级×0.05)
A28: 离线计时上限 12 小时（防纯挂机，同时保证次日回归有收益 → 这是次留的核心钩子）。
A29: 花盆：初始 2，最多 6。金币解锁成本 5,000 / 20,000 / 60,000 / 150,000。

Sheet 09_验收清单
A1: 平衡目标与 Broken 判定标准 —— playtest 前必读
A2: 原则：先定义「什么算坏」，才能在 playtest 中认出它。所有阈值在此表预先约定，不做事后解释。
A4: 健康指标（埋点目标）
A5: 类别 | B5: 指标 | C5: 目标区间 | D5: 低于下限的处置 | E5: 高于上限的处置
A6: 节奏 | B6: 每波步数消耗 | C6: 25 – 30 步 | D6: 步数回复过快或玩家不积极 → 降低回复速率 | E6: 步数不够用 → 提高回复速率或降低消耗
A7: 节奏 | B7: 每波合成次数 | C7: 30 – 40 次 | D7: 棋盘太挤或生成值过低 → 提升生成分层 | E7: 棋盘过于宽松 → 提升难度
A8: 节奏 | B8: 每波小附魔触发 | C8: 3 – 4 次 | D8: 充能条过高 → 降低 CHARGE_MAX | E8: 充能刷屏 → 升高 CHARGE_MAX（>6 必须处理）
A9: 节奏 | B9: 每波战术指令使用 | C9: 0.8 – 1.5 次 | D9: 星核产出不足 → 提高 K_STAR | E9: 指令续命 → 降低 K_STAR（>2 必须处理）
A10: 难度 | B10: 平均到达关卡 | C10: 4 – 6 关 | D10: 难度过高 → 降低 HP_BASE 至 1.50 | E10: 难度过低 → 升高 HP_BASE 至 1.60
A11: 难度 | B11: 第 1 关失败率 | C11: < 5% | D11: —（达标即可） | E11: 教学波设计失败，需重做波次组成
A12: 难度 | B12: 无养成新手到达 | C12: 3 关 | D12: 新手挫败 → 前 2 关难度下调 | E12: 元游戏无意义 → 前期难度上调
A13: 难度 | B13: 满养成高手到达 | C13: 9 – 11 关 | D13: 长线目标不足 → 提高养成上限 | E13: 养成碾压 → 压缩植物星级/等级成长
A14: 难度 | B14: 收工关卡众数 | C14: 第 4 – 6 关 | D14: 玩家不敢冒险 → 提高保底 b | E14: 玩家不敢收工 → 降低保底 b
A15: 留存 | B15: 单局时长 | C15: 12 – 20 分钟 | D15: 内容不足 → 增加波数或波次时长 | E15: 疲劳 → 缩短波次时长至 30s
A16: 健康 | B16: 棋盘卡死触发率 | C16: < 3% | D16: —（达标即可） | E16: 棋盘太小或生成算法有问题，需修伪随机
A18: Broken 判定（出现任一症状即为设计失败，需回头改系统而非改数值）
A19: 症状 | B19: 判定阈值 | C19: 根因假设 | D19: 处置
A20: 战斗毫无压力 | B20: 核心 HP 全损率 < 10% | C20: 敌人推进速度或数量不足 | D20: 提高速度缩放 SPD_SCL，或降低植物基础 DPS
A21: 棋盘被忽略 | B21: 步数常年满仓（余量 > 60%） | C21: 合成收益不足以驱动玩家操作 | D21: 提高 CV 转化系数，或降低步数回复速率
A22: 附魔刷屏 | B22: 每波小附魔 > 6 次 | C22: 充能条过低 | D22: 升高 CHARGE_MAX 至 130–150
A23: 卡牌无选择 | B23: 某张卡选取率 > 70% | C23: 该卡超模或同类卡过少 | D23: 削弱该卡，或补充 2–3 张同类竞品卡
A24: 经济通胀 | B24: 金币日增量 / 日消耗 > 3 | C24: 金币汇不足 | D24: 增设金币汇（新商店项），或降低 K_GOLD
A25: 元素单一最优解 | B25: 某元素使用率 > 50% | C25: 该元素超模，或克制设计未生效 | D25: 调整该元素数值，或增加对应护盾的精英出现率
A26: 后期棋盘饱和 | B26: 第 8 关后棋盘空格 < 3 | C26: 升华阈值过高 | D26: 降低 SUB_TH 至 256，或提高「贪婪核心」出现率
A27: 养成碾压局内 | B27: 满养成 vs 零养成可达关卡比 > 1.8 | C27: 植物星级/等级/编队位成长过大 | D27: 压缩 STAR_MULT / LV_MULT / SLOT_EFF
A28: 局内卡牌无意义 | B28: 满卡牌 vs 零卡牌可达关卡比 < 1.3 | C28: 卡牌效果或数量不足 | D28: 提高 CARD_PWR 或扩充卡池至 60 张
A30: 平衡流程（不可跳过）
A31: 阶段 | B31: 活动 | C31: 产出 | D31: 准入条件
A32: 1. 纸面模拟 | B32: Monte Carlo 跑 10,000 局 2048，统计 150 步内的最高方块分布、合成次数分布 | C32: 校准 MERGE_RATE 与平均合成值 | D32: 写代码之前完成
A33: 2. 数值原型 | B33: 只做棋盘 + 充能 + 附魔伤害的裸 Demo（无战斗） | C33: 验证乐趣假设：精准四连合成触发超载清屏的瞬间是否成立 | D33: 纸面模拟完成
A34: 3. 可玩原型 | B34: 加入战斗与波次 | C34: 验证压力曲线与注意力分配 | D34: 乐趣假设成立
A35: 4. 小规模测试 | B35: 20–50 人试玩，只观察 Feel 问题，不调数值 | C35: Feel 问题清单 | D35: 核心循环可玩
A36: 5. 数值调优 | B36: 基于埋点做回归分析 | C36: v0.2 数值 | D36: 埋点体系上线
A37: 6. 软启动 A/B | B37: 测三个主旋钮：STEP_REGEN / B_FAIL / HP_BASE | C37: 上线数值配置 | D37: 数值基本稳定
A40: 给开发团队的一句话
A41: V1 垂直切片是生死线。如果 V1（1 主植物 / 3 波 / 2 元素 / 10 张卡）玩起来不爽，加再多内容和养成也救不回来 —— 请在 V1 投入充分的试玩时间，而不是赶着堆内容。
